Workbook

Sheet Operations
C3: Assigment Group | D3: Component | E3: Category | F3: Subcategory
B4: Product Family | C4: Applications | D4: (Microservice/Interfaces/Module) | E4: Product | F4: Capability | G4: Business Product Owner | H4: Technical Product Owner | I4: Jira Key | J4: Jira Board | K4: Has Description
B5: Operations | C5: SG Delta | E5: Impact Management | F5: SG Delta | G5: Eduardo Fijnzylber | H5: Salazar Martin Gabriel | I5: IMMA | J5: https://iadb-ttd.atlassian.net/jira/software/c/projects/IMMA/ | K5: Yes
B6: Operations | E6: Impact Management | F6: Results Matrix | G6: TBD | H6: Salazar Martin Gabriel | J6: https://iadb-ttd.atlassian.net/jira/software/c/projects/IMMA/
B7: Operations | E7: Impact Management | F7: Catalog of Indicators | G7: Cecilia Vidal | H7: Salazar Martin Gabriel | J7: https://iadb-ttd.atlassian.net/jira/software/c/projects/IMMA/
B8: Operations | E8: Client Services | F8: Client Portal | H8: Theo Laguna | I8: CLIEN | K8: Yes
B9: Operations | C9: SISCOR | E9: Client Services | F9: Correspondence Management | H9: Theo Laguna | I9: CLIEN | K9: Yes
B10: Operations | E10: Fiduciary Management | F10: Fiduciary Management | H10: Robert Pierre | I10: CFI | K10: Yes
B11: Operations | E11: Fiduciary Management | F11: Fiduciary Interface | H11: Robert Pierre | I11: CFI | K11: Yes
B12: Operations | C12: Luca AI | E12: Fiduciary Management | F12: AI Assistant | H12: Robert Pierre | I12: CFI | K12: Yes
B13: Operations | C13: Knowledge Platform | E13: Knowledge Management | F13: Knowledge Platform | G13: Florencia Baudino | H13: Javier Fernandez Sanchez | I13: KNP | J13: https://iadb-ttd.atlassian.net/jira/software/c/projects/KNP | K13: Yes
B14: Operations | C14: lessons learned writing assistant | E14: Knowledge Management | F14: Knowledge Platform | G14: David Zepeda | I14: KNP | J14: https://iadb-ttd.atlassian.net/jira/software/c/projects/KNP
B15: Operations | C15: IE Evaluation Tracker | E15: Knowledge Management | F15: Knowledge Platform | G15: Magdalena Rosseti | I15: KNP | J15: https://iadb-ttd.atlassian.net/jira/software/c/projects/KNP
B16: Operations | C16: Evidence Gap MAP | E16: Knowledge Management | F16: Knowledge Platform | G16: Camilo Acosta | I16: KNP | J16: https://iadb-ttd.atlassian.net/jira/software/c/projects/KNP
B17: Operations | C17: Learning Data HUB | E17: Knowledge Management | F17: IDB Learning | G17: Caludia Useche | H17: Javier Fernandez Sanchez | I17: KNP | J17: https://iadb-ttd.atlassian.net/jira/software/c/projects/IL | K17: Yes
B18: Operations | C18: Course Portal | E18: Knowledge Management | F18: IDB Learning | G18: Caludia Useche | I18: KNP | J18: https://iadb-ttd.atlassian.net/jira/software/c/projects/IL
B19: Operations | C19: Meira | E19: Knowledge Management | F19: IDB Learning | G19: Stella Porto | I19: KNP | J19: https://iadb-ttd.atlassian.net/jira/software/c/projects/IL
B20: Operations | C20: Moodle | E20: Knowledge Management | F20: IDB Learning | G20: Stella Porto | I20: KNP | J20: https://iadb-ttd.atlassian.net/jira/software/c/projects/IL
B21: Operations | C21: EDX | E21: Knowledge Management | F21: IDB Learning | G21: Rodrigo Morosoli | I21: KNP | J21: https://iadb-ttd.atlassian.net/jira/software/c/projects/IL
B22: Operations | C22: Coursera | E22: Knowledge Management | F22: IDB Learning | G22: Rodrigo Morosoli | I22: KNP | J22: https://iadb-ttd.atlassian.net/jira/software/c/projects/IL
B23: Operations | C23: Publishing Workflow | E23: Knowledge Management | F23: Digital Library | G23: Kyle Strand | H23: Javier Fernandez Sanchez | I23: KNP | J23: https://iadb-ttd.atlassian.net/jira/software/c/projects/DL/list | K23: Yes
B24: Operations | C24: Catalogo de Publicaciones | E24: Knowledge Management | F24: Digital Library | G24: Kyle Strand | I24: KNP | J24: https://iadb-ttd.atlassian.net/jira/software/c/projects/DL/list
B25: Operations | C25: Open Data Portal | E25: Knowledge Management | F25: Digital Library | G25: Brandon Mora | I25: KNP | J25: https://iadb-ttd.atlassian.net/jira/software/c/projects/DL/list
B26: Operations | C26: Knowledge Graph | E26: Knowledge Management | F26: Digital Library | G26: Kyle Strand | I26: KNP | J26: https://iadb-ttd.atlassian.net/jira/software/c/projects/DL/list
B27: Operations | C27: Knowledge Taxonomy | E27: Knowledge Management | F27: Digital Library | G27: Maite Arakaki | I27: KNP | J27: https://iadb-ttd.atlassian.net/jira/software/c/projects/DL/list
B28: Operations | E28: Project Design | F28: Project Design | H28: Carlos Garcia | I28: PPD | K28: Yes
B29: Operations | E29: Programming | F29: Programming | H29: Norma Fleitas
B30: Operations | E30: Portfolio Management | F30: Geotagging | G30: No está priorizado para este año. No hay BPO | H30: Naily Contreras | I30: PMG | J30: https://iadb-ttd.atlassian.net/jira/software/c/projects/PMG/boards/1334 | K30: Yes
B31: Operations | E31: Portfolio Management | F31: Smart Porftolio | G31: Mariana Rosa Montegro (Licencia de maternidad) | H31: Maria Isabel Gomez Pineda | I31: PM | J31: https://iadb-ttd.atlassian.net/jira/software/c/projects/PM/boards/443 | K31: Yes
B32: Operations | E32: Project Risk | F32: ESG Compass | G32: María Isabel Gomez | H32: Naily Contreras | I32: OPR | J32: https://iadb-ttd.atlassian.net/jira/software/c/projects/OPR/boards/1165 | K32: Yes
B33: Operations | E33: Project Risk | F33: Risk Screening Tool | G33: Jaime de los Santos | H33: Naily Contreras | I33: RIMA | J33: https://iadb-ttd.atlassian.net/jira/software/c/projects/RIMA/boards/1331 | K33: Yes
B34: Operations | E34: Core Services & Operational Portal | F34: Operational Portal | G34: Natalia Benasso | H34: Daniel Aronne | I34: OP | J34: https://iadb-ttd.atlassian.net/jira/software/c/projects/OP/ | K34: Yes
B35: Operations | E35: Resources Mobilization and Grants Management Budget Performance | F35: Performance | H35: Nicolas Moreno Montoya | I35: RM | K35: Yes
B36: Operations | C36: SAP | D36: Grants Master Data | E36: Resources Mobilization and Grants Management Budget Performance | F36: SAP Reporting
B37: Operations | C37: SAP | D37: Billing & Collections | E37: Resources Mobilization and Grants Management Budget Performance | F37: SAP Reporting
B38: Operations | C38: SAP | D38: Fees & Returns | E38: Resources Mobilization and Grants Management Budget Performance | F38: SAP Reporting
B39: Operations | C39: SAP | D39: GCM Reports | E39: Resources Mobilization and Grants Management Budget Performance | F39: SAP Reporting
B40: Operations | C40: SAP | D40: GRF / ORC Budget Control | E40: Resources Mobilization and Grants Management Budget Performance | F40: SAP Reporting
B41: Operations | C41: SAP | D41: Convergence (GCM) | E41: Resources Mobilization and Grants Management Budget Performance | F41: SAP Reporting
B42: Operations | C42: SAP | D42: GCM Integrators | E42: Resources Mobilization and Grants Management Budget Performance | F42: SAP Reporting
...

Sheet Finance & Enterprise
C2: Assigment Group | D2: Category | E2: Subcategory | F2: Component (Optional)
B3: Product Family | C3: Applications | D3: Product | E3: Capability | F3: (Microservice/Interfaces/Module) | G3: Business Product Owner (Change Approver) | H3: Technical Product Owner | I3: Jira Key | J3: Jira Board | K3: Has Description
B4: Enterprise and Finance | C4: LFM | D4: Development Assets | E4: Accounting and Servicing | F4: Access/Security Accounting Audit Arrears BDU Billing/Invoices Collections Disbursements Fin Terms Interfaces Jobs Master Data Other | G4: Jaime Cabrera; Alejandro Leal | H4: Dunn, Steve | I4: DA | J4: https://iadb-ttd.atlassian.net/jira/software/c/projects/DA/boards/245 | K4: Yes
B5: Enterprise and Finance | C5: LFM | D5: Development Assets | E5: Reporting | F5: Reports/Views | G5: Jaime Cabrera; Alejandro Leal | H5: Dunn, Steve | I5: DA | J5: https://iadb-ttd.atlassian.net/jira/software/c/projects/DA/boards/245 | K5: Yes
B7: Enterprise and Finance | C7: SAP SuccessFactors | D7: People Management | E7: Talent Management | F7: Talent+ (SAP SuccessFactors) | G7: Leony, Larissa | H7: Majus Fernandez, Erick | I7: TM | J7: https://iadb-ttd.atlassian.net/jira/software/c/projects/TM/boards/2487 | K7: Yes
B8: Enterprise and Finance | C8: Alcatraz | D8: Corporate Workplace Place Solutions | E8: Workplace Solutions | F8: Workplace Management | G8: Herrera, Mariasol | H8: Carvajal Monge, Katherine Johanna | I8: TWS | J8: https://iadb-ttd.atlassian.net/jira/software/c/projects/TWS/boards/1277 | K8: Yes
B9: Enterprise and Finance | C9: Quantum | D9: Cash & Settlements | E9: Cash Reconciliation | G9: Estrada Vazquez, Alejandra Isabel | H9: Mauricio Angeles | I9: CAS | J9: https://iadb-ttd.atlassian.net/jira/software/c/projects/CAS/boards/94 | K9: Yes
B10: Enterprise and Finance | C10: Swift | D10: Cash & Settlements | E10: Settlements (confimation and documentation) | G10: Estrada Vazquez, Alejandra Isabel | H10: Mauricio Angeles | I10: CAS | J10: https://iadb-ttd.atlassian.net/jira/software/c/projects/CAS/boards/95 | K10: Yes
B11: Enterprise and Finance | C11: Fedline | D11: Cash & Settlements | E11: Liquidity | G11: Estrada Vazquez, Alejandra Isabel | H11: Mauricio Angeles | I11: CAS | J11: https://iadb-ttd.atlassian.net/jira/software/c/projects/CAS/boards/95 | K11: Yes
B12: Enterprise and Finance | C12: Summit | D12: Cash & Settlements | E12: Settlements
B13: Enterprise and Finance | C13: Mutual Funds | D13: Cash & Settlements
B14: Enterprise and Finance | C14: SSI Importer | D14: Cash & Settlements
B18: Enterprise and Finance | D18: Treasury | E18: Treasury Risk Management | G18: Ruiz Garcia, F. Ramon; Ciecka, Peter | H18: Pizzirani, Rafael | I18: TREAS | J18: https://iadb-ttd.atlassian.net/jira/software/c/projects/TREAS/boards/1696 | K18: Yes
B19: Enterprise and Finance | C19: SSI | D19: Treasury | E19: Treasury Risk Management | G19: Ruiz Garcia, F. Ramon; Ciecka, Peter | H19: Pizzirani, Rafael | I19: TREAS | J19: https://iadb-ttd.atlassian.net/jira/software/c/projects/TREAS/boards/1696 | K19: Yes
B20: Enterprise and Finance | C20: Frida | D20: Treasury
B21: Enterprise and Finance | C21: COB Allocation | D21: Treasury
B22: Enterprise and Finance | C22: Mutual funds | D22: Treasury
B23: Enterprise and Finance | C23: File Converter | D23: Treasury
B24: Enterprise and Finance | C24: EIS | D24: Treasury
B25: Enterprise and Finance | C25: DailyPL Adjusments | D25: Treasury
B26: Enterprise and Finance | C26: GLI | D26: Treasury
B27: Enterprise and Finance | C27: Raiting Imports | D27: Treasury
B28: Enterprise and Finance | C28: Summit | D28: Treasury
B32: Enterprise and Finance | C32: SAP | D32: Financial Reporting | E32: Financial Reporting | F32: Asset Accounting | G32: Kukreja, Rekha | H32: Morales Serrato, Paloma Libertad | I32: FR | J32: https://iadb-ttd.atlassian.net/jira/software/c/projects/FR/boards/1660 | K32: Yes
B33: Enterprise and Finance | C33: SAP | D33: Financial Reporting | E33: Financial Reporting | F33: Bank Accounting | G33: Kukreja, Rekha | H33: Morales Serrato, Paloma Libertad | I33: FR | J33: https://iadb-ttd.atlassian.net/jira/software/c/projects/FR/boards/1661 | K33: Yes
B34: Enterprise and Finance | C34: SAP | D34: Financial Reporting | E34: Financial Reporting | F34: GL Financial Statement Processsing | G34: Kukreja, Rekha | H34: Morales Serrato, Paloma Libertad | I34: FR | J34: https://iadb-ttd.atlassian.net/jira/software/c/projects/FR/boards/1662 | K34: Yes
B35: Enterprise and Finance | C35: SAP | D35: Financial Reporting | E35: Financial Reporting | F35: GL Administration & Troubleshooting | G35: Kukreja, Rekha | H35: Morales Serrato, Paloma Libertad | I35: FR | J35: https://iadb-ttd.atlassian.net/jira/software/c/projects/FR/boards/1663 | K35: Yes
B36: Enterprise and Finance | C36: SAP | D36: Financial Reporting | E36: Financial Reporting | F36: GL Analytics & Reportinhg | G36: Kukreja, Rekha | H36: Morales Serrato, Paloma Libertad | I36: FR | J36: https://iadb-ttd.atlassian.net/jira/software/c/projects/FR/boards/1664 | K36: Yes
B37: Enterprise and Finance | C37: SAP | D37: Financial Reporting | E37: Financial Reporting | F37: GL Financial Master Data | G37: Kukreja, Rekha | H37: Morales Serrato, Paloma Libertad | I37: FR | J37: https://iadb-ttd.atlassian.net/jira/software/c/projects/FR/boards/1665 | K37: Yes
B38: Enterprise and Finance | C38: SAP | D38: Financial Reporting | E38: Financial Reporting | F38: GL Financial Closing | G38: Kukreja, Rekha | H38: Morales Serrato, Paloma Libertad | I38: FR | J38: https://iadb-ttd.atlassian.net/jira/software/c/projects/FR/boards/1666 | K38: Yes
B39: Enterprise and Finance | C39: SAP | D39: Financial Reporting | E39: Financial Reporting | F39: GL House Banks Management | G39: Kukreja, Rekha | H39: Morales Serrato, Paloma Libertad | I39: FR | J39: https://iadb-ttd.atlassian.net/jira/software/c/projects/FR/boards/1667 | K39: Yes
B40: Enterprise and Finance | C40: SAP | D40: Financial Reporting | E40: Financial Reporting | F40: GL Manage Journals | G40: Kukreja, Rekha | H40: Morales Serrato, Paloma Libertad | I40: FR | J40: https://iadb-ttd.atlassian.net/jira/software/c/projects/FR/boards/1668 | K40: Yes
B41: Enterprise and Finance | C41: SAP | D41: Financial Reporting | E41: Financial Reporting | F41: GL Payroll Posting | G41: Kukreja, Rekha | H41: Morales Serrato, Paloma Libertad | I41: FR | J41: https://iadb-ttd.atlassian.net/jira/software/c/projects/FR/boards/1669 | K41: Yes
B42: Enterprise and Finance | C42: SAP | D42: Financial Reporting | E42: Financial Reporting | F42: FR Integrations + TC Integrations | G42: Kukreja, Rekha | H42: Morales Serrato, Paloma Libertad | I42: FR | J42: https://iadb-ttd.atlassian.net/jira/software/c/projects/FR/boards/1670 | K42: Yes
B43: Enterprise and Finance | C43: ? | D43: Risk, Audit & Compliance | E43: Oversight | F43: Audit | G43: Garay Fernandez, Luis Andres | H43: Yec Lay, Alexander A | I43: AO | J43: https://iadb-ttd.atlassian.net/jira/software/c/projects/AO/boards/868 | K43: Yes
... B50: Enterprise and Finance | C50: ALM | D50: Risk, Audit & Compliance | E50: Risk Financial and Non Financial | F50: Data Interface App/SaaS SSO | G50: Cieka, Peter/Marcelo Gordillo, Darwin | H50: Carranza Motta, Rossana Estela | I50: FNR | J50: https://iadb-ttd.atlassian.net/jira/software/c/projects/FNR/boards/1000 | K50: Yes

Sheet Enablers
C3: Assigment Group | D3: Category | E3: Subcategory
B4: Product Family | C4: Applications (Microservice/Interfaces/Module) | D4: Enabler | E4: Capability | F4: Jira Key | G4: Jira Board | H4: Has Description
B5: Enblers | C5: ServiceNow | D5: Business Process Management (BPM) | E5: ServiceNow | F5: BPM
B6: Enblers | C6: UiPath | D6: Business Process Management (BPM) | E6: UiPath | F6: BPM
B7: Enblers | C7: Power Platforms | D7: Business Process Management (BPM) | E7: Power Platforms | F7: BPM
B8: Enblers | C8: (Record Management System EzShare, Siscor, Enterprise Search ) | D8: Content Management | E8: Record Management | F8: CM
B9: Enblers | C9: Salesforce | D9: External Customer Management | E9: Marketing Cloud | F9: ECM
B10: Enblers | C10: Salesforce | D10: External Customer Management | E10: CRM | F10: ECM
B11: Enblers | C11: Drupal, Pantheon | D11: External Communications | F11: EEC
B12: Enblers | C12: My IDB, Intranet, Exchange, BananaTag, Viva Engage | D12: Employee Communications | F12: ICP
B13: Enblers | D13: Collaborations and Productivity | F13: ICP
B14: Enblers | D14: Developer Platform (DX) | E14: Enabler | F14: DX
D15: Developer Platform (DX) | E15: Cloud Solutions | F15: DX
B16: Enblers | C16: (Biztalk, API Management, Enterprise Service Bus) | D16: Developer Platform (DX) | E16: Integrations | F16: INT
B17: Enblers | C17: AWS, Azure | D17: Cloud Operations | E17: Cloud Operations, Engineering and Security (ECOES) | F17: ECOES
B18: Enblers | D18: Cloud Operations | E18: Cloud Strategy and Cost Management (ECSCM) | F18: ECSCM
B19: Enblers | D19: Cloud Operations | E19: Enterprise Communications and Networking (Cloud) (EECNC) | F19: EECNC
B20: Enblers | D20: Cloud Operations | E20: Digital Workplace Infrastructure (O365) | F20: DWI
B21: Enblers | D21: Cloud Operations | E21: Identity and Access Management (Cloud) (EIAMC) | F21: EIAMC
B22: Enblers | D22: IT Risk (Compliance) | E22: Audit | F22: ECOMP | H22: Yes
B23: Enblers | D23: IT Risk (Compliance) | E23: Automated Controls | F23: ECOMP | H23: Yes
B24: Enblers | D24: IT Risk (Compliance) | E24: Comtinuos monitoring | F24: ECOMP | H24: Yes
B25: Enblers | D25: Cybersecurity | E25: Security Assurance | F25: ECYBER | H25: Yes
B26: Enblers | D26: Cybersecurity | E26: Enginnering Design | F26: ECYBER | H26: Yes
B27: Enblers | D27: Cybersecurity | E27: Security Operations | F27: ECYBER | H27: Yes
B28: Enblers | D28: Data Management | E28: Business Intelligence | F28: DMP | H28: Yes
B29: Enblers | D29: Data Management | E29: DB Admin | F29: DMP | H29: Yes
B30: Enblers | D30: Data Management | E30: Data Gov & QA | F30: DMP | H30: Yes
B31: Enblers | D31: Data Management | E31: Data Pipelines and Analytics | F31: DMP | H31: Yes
B32: Enblers | D32: Artificial Intelligence | F32: AIP | H32: Yes
B33: Enblers | D33: Enterprise Architecture | E33: Application Portfolio Management | F33: EEARCH | H33: Yes
B34: Enblers | D34: Enterprise Architecture | E34: Co-Design & Architecture Support for Products | F34: EEARCH | H34: Yes
B35: Enblers | D35: Enterprise Architecture | E35: Architecture Advisory | F35: EEARCH | H35: Yes
B36: Enblers | D36: Enterprise Architecture | E36: Technology & Architecture Standards | F36: EEARCH | H36: Yes
B37: Enblers | D37: Service Delivery | F37: SD | H37: Yes
B38: Enblers | D38: Strategic Resource Management | E38: Budget Management | F38: Not Available | H38: Yes
B39: Enblers | D39: Strategic Resource Management | E39: Vendor Management | F39: Not Available | H39: Yes
B40: Enblers | D40: Strategic Resource Management | E40: CIO Office Support | F40: Not Available | H40: Yes
B41: Enblers | D41: Strategic Resource Management | E41: Resource Administration | F41: Not Available | H41: Yes
B42: Enblers | D42: People Experience - IBT | E42: Communications | F42: IBT | H42: Yes
...

Sheet Reviewed Product Fact Sheet
A1: Product or Enabler Name | B1: Family | C1: Description | D1: Function | E1: Jira Board | F1: Organizational Goals | G1: Responsible: (Product/Enabler Lead) | H1: Responsible: (Technical Lead/Technical Product Owner) | I1: Value Proposition (Problem / Opportunity Statement ) | J1: Systems Used (Critical Integrations) | K1: Capabilities (Business Services) | L1: Has Description (Col H) | M1: PEro
A2: Adoption & Experimentation Infrastructure | B2: Technology and Transformation in the Region | C2: This product delivers a secure and scalable cloud ecosystem—IDBCloud4LAC—designed to accelerate the adoption of digital solutions across Latin America and the Caribbean. It provides a trusted environment that enables Sector teams to support local governments and institutions in experimenting with and adopting digital tools without the infrastructure barriers that often delay delivery. The IDB is extending its support to the region by providing an environment for solutions to be put into production and operated until the local governments or entities are ready to take over. | D2: Product | E2: Pending | F2: Bolstering Sustainable Regional Growth: by providing the digital infrastructure needed to accelerate innovation, strengthen institutional capacity, and enhance the delivery of public services. Reduce Poverty and Inequality: by enabling governments and institutions to quickly deploy digital tools that improve the delivery of public services in areas such as education, health, food security, and gender equality. (These are also the business goals for the overall TTR Digital Interventions product family). Reduce Poverty and Inequality: by enabling governments and institutions to quickly deploy digital tools that improve the delivery of public services in areas such as education, health, food security, and gender equality. | G2: LEEU@iadb.org | I2: Many institutions across LAC lack the technical infrastructure, capacity, or security controls to quickly deploy and manage digital solutions. As a result, innovative projects often face long delays, high costs, and elevated risks related to system performance, data protection, and sustainability. The product addresses the issue of developed solutions not being put into production due to lack of infrastructure or readiness by recipient institutions, leading to wasted effort and delayed impact (e.g., solutions taking years to go live). | J2: None | K2: Infrastructure enablement - Providing a secure and scalable cloud environment (IDBCloud4LAC) where digital solutions can be hosted, allowing acceleration of adoption without local infrastructure barriers. Security and Risk Mitigation - Solutions hosted on the platform comply with minimum security policies and controls, including hardening sites, setting up firewalls (e.g., Cloudflare), and monitoring for breaches or attacks to mitigate reputational risk. Interoperability and Reusability - Promoting the development and use of interoperable and reusable digital solutions by creating independent infrastructures for each project to avoid affecting others. The platform is agnostic to technology, allowing solutions developed with various technologies (e.g., MySQL, Java) to be hosted. Monitoring and Management Tools - Providing centralized oversight of hosted solutions, monitoring usage, security, and analytics, and generating monthly reports on security attempts, backups, and site usage. Advisory and Support Services - Offering specialized advisory services to help teams design, deploy, and maintain high-quality digital solutions, including providing architecture and security expertise for meetings with institutions. This also includes reminding business partners about contract and domain renewal dates. | L2: =IF(ISBLANK(H2),"No","Yes") -> No | M2: =IF(OR(COUNTIF('Finance & Enterprise'!D:D,A2)>0,COUNTIF(Operations!E:E,A2)>0,COUNTIF(Enablers!D:D,A2)>0),"Yes","No") -> No
A3: Enterprise Architecture | B3: Technology and Data Assurance | C3: Enables modular, scalable, and AI-driventechnology solutions, ensuring reusability, flexibility, and efficiency in IDB’s digital transformation. By aligning architecture with Development Operations, AI adoption, application portfolio optimization, and core building blocks design, EA will accelerate the bank’s ability to deliver strategic reforms, enhance operational resilience, and maximize impact in sustainable regional growth. | D3: Enabler | E3: https://iadb-ttd.atlassian.net/jira/software/c/projects/EEARCH/boards/83 | F3: Using KPIs to measure impact (specifically adherence to architecture standards like the IDB Technological Framework) Measure performance (e.g., reducing application load time, improving responsiveness of applications for country offices). Simplify the use of technology for the users (reducing fragmentation and entangled processes). Aligning sourcing, delivery, and governance around EA strengthens the Bank’s capacity to deliver with speed, purpose, and coherence Promote reuse (e.g., shared components for digital experiences like user profiles and authentication, rationalizing and reusing applications). Promote the responsible use and adoption of AI (defining AI building blocks and target roadmap for adoption, clarifying AI governance). Foster a culture of reuse and fiscal sustainability. Push for technical excellence and operational resilience. | G3: KARLAVI@IADB.ORG | H3: RauldaSilva | I3: Problem-solving, value, intentional, and a clear goal of where we are going. Enterprise Architecture aims to address issues like duplication, misalignment, and fragmentation within the bank's technological landscape, reducing complexity and improving decision-making by understanding the distinct value the user gets from interacting with the product or enabler. It seeks to define the overall technology strategy and provide advisory and oversight for product teams, ensuring cohesion and proper design across the bank's digital solutions | J3: Digital Portfolio - Digital channel (website) for digital solutions portfolio, using Lean IX as a backend. Open AI - Creating chatbots for the technology catalog, and as an AI enabler for digital channels and operations. Service Now - Process for new license subscriptions. Key dependency for exploiting Lean IX capabilities by enabling checks against inventory before approval. Jira - Ticketing and user story management. Datadog - Observability and monitoring tool used for performance dashboards. Potential for installation on corporate side (SAP). SharePoint/ezShare - Purpose of Integration: Documenting standards; Easy Share for document handling. LeanIx - Backend for Digital Solutions portfolio, technology portfolio management, and technology inventory. | K3: Technology Strategy - Defining how technology supports bank objectives and how technological assets should be used. This includes defining guidelines for buy vs. build decisions, creating long-term strategies (target architecture), and helping product teams define their own target and transition architectures. Software Architecture - Deep dive into requirements, including co-design sessions with product owners, UX, and technology leaders to find better solutions for institutional reach projects (e.g., reforms, knowledge platform). Includes creating architectures and working with tech leads for implementation. Technology Catalog (or Technology Portfolio Management / Technology Inventory Management) - Managing the list of applications and IT components across the bank, understanding relationships, and identifying usage. Aims to incorporate business objectives, interfaces, data objects, and resource management variables for proper technology feasibility assessment and rationalization opportunities (e.g., sunsetting redundant applications). Involves a recertification process every six months and aims for automated data ingestion. Assurance - Ensuring that products follow defined standards (from Technology Strategy service) throughout their lifecycle and achieve technical KPIs (e.g., performance). Works in a matrixed way with tech leads to understand implementation challenges and refine standards. Aims to create a heat map showing compliance status (Green, Yellow, Red) for various technology components. | L3: =IF(ISBLANK(H3),"No","Yes") -> Yes | M3: =IF(OR(COUNTIF('Finance & Enterprise'!D:D,A3)>0,COUNTIF(Operations!E:E,A3)>0,COUNTIF(Enablers!D:D,A3)>0),"Yes","No") -> Yes
A4: Artificial Intelligence | B4: Technology and Data Solutions | C4: The AI enabler is IDB's cross-cutting AI capability team, equipping product and enabler teams with the platforms, frameworks, and expertise to embed intelligence responsibly into what they build. It defines and owns the corporate AI strategy and execution roadmap, builds and operates shared enterprise AI capabilities, and ensures AI adoption remains compliant with the Bank-wide AI Framework and golden rules while avoiding duplication of AI capabilities across the institution. | D4: Enabler | E4: https://iadb-ttd.atlassian.net/jira/software/c/projects/AIP/boards/312 | F4: AI-enabled IDB: equip product teams to innovate with shared AI capabilities, empower every team member to work smarter, and amplify development impact across LAC. Establish and maintain the Bank-wide AI Framework, guidelines, and golden rules. Promote responsible, ethical, and secure AI adoption — transparency, explainability, and traceability of agents. Reduce duplication and optimize resources across AI initiatives bank-wide. | G4: JAIRORI@IADB.ORG | I4: Enable every product and enabler team at IDB to embed AI safely and quickly by providing shared, ready-to-use platform capabilities — the Unstructured Data Application, MCP servers for Denodo, Convergence, and sgDELTA, and centralized agent skills — so teams innovate faster without duplicating infrastructure, expertise, or governance effort. | J4: AI Gateway - Shared and dedicated model gateway for AI consumption bank-wide (in production). Unstructured Data Application - Platform replacing Aurora for unstructured/vectorized data (in test). MCP Servers - Model Context Protocol servers for Denodo, Convergence, and sgDELTA (in test). Agents Skills Administrator - Centralized repository for reusable agent skills across the Bank. AI Risk Assessment (AIRA) - Risk assessment tool for AI initiatives (in test). Aurora / SAIA 1.0 - Legacy RAG SaaS chatbot platform, in decommissioning process. Copilot Studio - Platform for agent development and pre-production agent evaluation. | K4: Strategy & Roadmap: Co-define and own the corporate AI capability strategy and execution roadmap with the Tech Office (TDA, TDS) and DT. Platform Development: Design, build, and integrate reusable enterprise AI capabilities — including the Unstructured Data Application, MCP Denodo, MCP Convergencia, and MCP sgDelta — from MVP through production, maintaining the enterprise AI capability catalogue. Ops & Lifecycle Management: Operate and continuously improve AI platform capabilities in production, including the migration from Aurora/SAIA to the Unstructured Data Application. Agent Skill Administrator: Operate the centralized repository for reusable agent skills across the Bank, enabling product and enabler teams to discover, reuse, and standardize agent capabilities instead of rebuilding them. Agent Build & Co-Build: Build or co-build bankwide agents and high-importance use cases directly with product and enabler teams, from MVP through production. Product Enablement & Advisory: Establish AI implementation standards and consumption guidelines for teams engaging with shared AI capabilities. Observability, Performance & Cost: Monitor reliability, performance, cost, and usage of enterprise AI capabilities, reporting to TDA governance. Innovation & Ecosystem: Co-own evaluation of emerging AI technologies and vendor solutions with the Tech Lab, running strategic PoCs (e.g. pre-production copilot agent evaluation). Adoption, Comms & Knowledge: Co-lead AI awareness, training, and knowledge assets with IBT and DT to drive responsible adoption bank-wide. | L4: =IF(ISBLANK(H4),"No","Yes") -> No | M4: =IF(OR(COUNTIF('Finance & Enterprise'!D:D,A4)>0,COUNTIF(Operations!E:E,A4)>0,COUNTIF(Enablers!D:D,A4)>0),"Yes","No") -> Yes
A5: Cash & Settlements | B5: Enterprise and Finance | C5: The Cash and Settlements product manages all systems and processes required to make and receive payments from various counterparts. It supports the end-to-end settlement of treasury cash operations, including individual and mass payments, as well as the reconciliation of transactions. This product ensures the timely, accurate, and secure movement of funds across the Bank’s operations. | D5: Product | E5: https://iadb-ttd.atlassian.net/jira/software/c/projects/CAS/boards/26 | F5: Keep up-to-date systems, modernization of procedures, and ensure efficient operations. Increase Straight Through Processing (STP) to automate transactions and reduce manual intervention. Achieve automatic reconciliations for all financial transactions. | G5: JUANFP@iadb.org | I5: The product is critical for settling transactions and handling cash and treasury transactions efficiently. It aims to increase straight-through processing (STP) and enable automatic reconciliations to minimize manual intervention and improve efficiency. | J5: Treasury (TMS) - Exchange cash and security messages. SAP - Process expected contributions, payroll, and procure-to-pay transactions. Systems IDB Invest (Maestro, TFFP, ACBS) - Handle Treasury and TFFP related transactions, including guarantees. Swift network - External dependency for sending and receiving all types of SWIFT messages (wires, ACH/batch, guarantees). LFM - Process disbursement requests from the loan system, acting as a conduit to the SWIFT network. | K5: Pay and receive cash - Handling all payments and receipts of cash for the bank, serving as a central hub for cash transactions. Settle financial securities transactions - Managing the process to settle investment and funding transactions in the treasury area, including exchanging SWIFT messages with counterparties. Reconciliation - Ensuring all payments and receipts are properly recorded and matched against statements, covering both intraday and prior day reconciliation. Delivering and Receiving Statements - Processing incoming statements and delivering cash position information to other bank systems. | L5: =IF(ISBLANK(H5),"No","Yes") -> No | M5: =IF(OR(COUNTIF('Finance & Enterprise'!D:D,A5)>0,COUNTIF(Operations!E:E,A5)>0,COUNTIF(Enablers!D:D,A5)>0),"Yes","No") -> Yes
A6: Client Services | B6: Operations | C6: Client Services delivers digital solutions to our external clients, ensuring a cohesive and meaningful experience with the IDB. | D6: Product | E6: Pending | F6: Absorption of knowledge, lessons learned for similar projects or other regions. | G6: katiac@iadb.org | H6: theoa@iadb.org Luis Garcia Castro | I6: Client Services digitalizes previously paper processes and creates a single point of entry for our clients. The opportunity is to address the decentralized experience clients previously had, where they navigated multiple tools with different logins; this product centralizes access to project info, contracts, and financial data. | J6: Convergence - Does not exist. Wishful thinking for real-time connection; currently non-existent. - DENODO datamarkeplace - Not created for real-time consumption. Used to bridge data from IDB Data Warehouse; performance issues during high traffic. Azure B2C - Authentication/Login system. External Account Provisioning System (EAPS) - Should be a unique context; currently have one for portal and one for others. Salesforce CRM - Account management module. Used for onboarding; relies on fragile BizTalk integration. Cartera inteligente - Portfolio review, agreements. Fiduciary Interface - Read data from the interface. For disbursements and procurement. ezShare - Sending semi-annual project report to be saved as a project document. | K6: Provide access to project financial information - Users can see advances, financial balances, among others. Provide access to project operational information - Risk matrix, operational balance, portfolio review agreement. Currently relies on Data Warehouse (not source), causing latency. Progress Reporting - Through semi-annual reports, results matrix. Currently relies on PDF generation due to lack of integration with Convergence. | L6: =IF(ISBLANK(H6),"No","Yes") -> Yes | M6: =IF(OR(COUNTIF('Finance & Enterprise'!D:D,A6)>0,COUNTIF(Operations!E:E,A6)>0,COUNTIF(Enablers!D:D,A6)>0),"Yes","No") -> Yes
A7: Cloud and Infrastructure | B7: Technology and Data Solutions | C7: The Cloud and Infrastructure enabler provides the foundational technology platforms and services that power the Bank’s digital ecosystem. It is responsible for defining and executing the cloud strategy, including cost management, secure operations, and engineering practices. The enabler supports DevSecOps and integration services to streamline development and deployment across environments. It also manages identity and access provisioning, directory services, and enterprise communication infrastructure—including telecommunications and network operations. Additionally, it delivers robust, scalable infrastructure solutions to support the Bank’s mission-critical operations, ensuring performance, availability, and security across all platforms. | D7: Enabler | E7: https://iadb-ttd.atlassian.net/jira/software/c/projects/ECLIN/boards/201 | F7: TTD aligment with HRD goals (3 goals) TTD Goal 1: Enhanced Bank Operations with Technology and Innovation TTD Goal 4: Digitalize and run our corporate and operational platforms TTD Goal 5: Build the future-ready workforce | G7: Egdares Futch EGDARESF@IADB.ORG | I7: Deliver reliable, secure, and high-performing cloud platforms, network infrastructure, and identity access management services that enable seamless connectivity, secure access, and digital operations, ensuring comprehensive implementation, proactive management, and continuous optimization of all technology infrastructure and access control services. | J7: AWS Azure Physical network providers Sailpoint Directory Services | K7: Cloud Strategy and Cost Management: Manage financial Operations integration with SaaS and cloud and strategic objectives Cloud Operations, Engineering and Security: Manage cloud operations ans resilience eans 365 and serverless computing and the automation development support Identity and Access Management: Provishioning automation and support, drectory servicces integration and SAP security engeneering Enterprise communications and networking: Networking, cloud service delivery and observability and voice communications, all network infrastructure | L7: =IF(ISBLANK(H7),"No","Yes") -> No | M7: =IF(OR(COUNTIF('Finance & Enterprise'!D:D,A7)>0,COUNTIF(Operations!E:E,A7)>0,COUNTIF(Enablers!D:D,A7)>0),"Yes","No") -> No
A8: Core Platforms | B8: Technology and Data Solutions | C8: The Core Platforms Enabler is dedicated to administering, managing, consolidating, and optimizing our foundational technology platforms—such as Salesforce, O365, SharePoint, and ServiceNow—to ensure they effectively support our business products. By providing a reliable technology foundation, we enable seamless software product delivery, offer advisory services, and empower users with scalable, high-performance solutions. | D8: Enabler | E8: https://iadb-ttd.atlassian.net/jira/software/c/projects/DX/boards/148 | F8: Efficiency (automation, process management) Security Data-driven (provide data in different systems) decision making process Compliance Reliability History of the institution (traceability, institutional memory) Standardization | G8: JUANAA@iadb.org | I8: Provide foundational services that help accelerate the deployment of other solutions, enable scaling of systems for corporate use, improve developer experience, and provide reliability. | J8: Cyberark - Security Sailpoint - Identity and Access Management (Inferred) Microsoft and Azure services - Active Directory , MFA,Microsoft services Denodo - Reliability and performance for transactional and analytical data Operational solutions - Convergence (data for applications like ATI, Fiduciary Interface, publications website) | K8: Business process management - Jira, SNow, Uipath, power platform External customer management - Salesforce External communications - Website (drupal, pantheon) Employee communication - Intranet, Viva tools Integrations - Biztalk, API management, Service Bus Development platform - Terraform, CICD Content management - ezShare, web services, onedrive, teams documents, SharePoint docs, DocuSign, search, e-disposition of records Collaboration and productivity - Office tools (MS teams, copilot, miro) | L8: =IF(ISBLANK(H8),"No","Yes") -> No | M8: =IF(OR(COUNTIF('Finance & Enterprise'!D:D,A8)>0,COUNTIF(Operations!E:E,A8)>0,COUNTIF(Enablers!D:D,A8)>0),"Yes","No") -> No
A9: Corporate Services | B9: Enterprise and Finance | C9: SAP Procurement, travel, budgeting, account payable, workplace solutions. | D9: Product | E9: https://iadb-ttd.atlassian.net/jira/software/c/projects/TWS/boards/1277 | F9: Streamlines and modernizes core administrative services. A efficient, economical acquisition of goods and services. A smooth and efficient travel service to the whole bank. | G9: KJOHANNAC@IADB.ORG | I9: Providing reliable automations to support the corporate services of the bank. | J9: SAP - S4 Hana SAP Ariba SAP BTP AppZen SAP Concur Ccure | K9: Travel Booking Spend Travel Expenses and Reporting Parking - Part of Workplace Management & Sustainability Sourcing and contracting - *Image information Invoice processing - *Image information Payment processing - *Image information Budget management - *Image information (Hyperion) Budget management - *Image information (Hyperion) space management - Part of Travel Management Sustainability initiatives - Part of Workplace Management & Sustainability Transfer - Part of Budget Real Estate Portfolio Management - Part of Workplace Management & Sustainability Physical Security & Access Control - Part of Workplace Management & Sustainability Execution - Part of Budget Modeling - Part of Budget Formulation - Part of Budget Expenditure control - Part of Budge | L9: =IF(ISBLANK(H9),"No","Yes") -> No | M9: =IF(OR(COUNTIF('Finance & Enterprise'!D:D,A9)>0,COUNTIF(Operations!E:E,A9)>0,COUNTIF(Enablers!D:D,A9)>0),"Yes","No") -> No
A10: Cybersecurity | B10: Technology and Data Assurance | C10: The Cybersecurity enabler is responsible for ensuring the protection, resilience, and compliance of digital assets across the organization. It supports strategic and operational security through a wide range of capabilities, including Security Assurance, ISO 27001 Information Security Management System (ISMS) operations, and audit management. The enabler drives a culture of security awareness via training, phishing simulations, and the development of Security Champions among developers. It provides technical expertise in secure architecture and engineering, cloud and API security, DevSecOps, and vulnerability management across infrastructure, servers, and cloud environments. Additionally, the team leads efforts in application security reviews (PRACs), cloud risk assessments (CRAs), penetration testing, threat intelligence, monitoring and detection, incident response, and compliance validation. Cybersecurity also manages key security tools and technologies to ensure end-to-end protection and continuous improvement of the organization’s security posture.Cybersecurity is the enabler product that ensures the security of information of the bank, develops the policies that everyone needs to follow, and operates the security tools that prevent, identify, and respond to cybersecurity incidents. | D10: Enabler | E10: https://iadb-ttd.atlassian.net/jira/software/c/projects/ECYBER/boards/98 | F10: Ensure the data is available, confidential, and adequately protected as per bank's needs. Enable the bank to keep its credit ratings (based on operational risk levels). Enhance the reputation of the bank towards stockholders, member countries, and clients. Overall business service delivery. Protecting the bank against malicious impacts (controlling, monitoring). Risk-oriented approach. Continuously enhance cybersecurity awareness. Establish and maintain a risk-based Cybersecurity Program to safeguard the confidentiality, integrity, and availability of data while supporting the Digital Transformation and IT Strategy. Establish a robust framework that promotes ongoing evaluation, enhancement, and adherence to industry-accepted security best practices. | G10: harleyj@IADB.ORG | I10: We ensure that the information that business products manage is secure, from secure software development, secure design, secure implementation, secure monitoring, operation of systems, and response. | J10: SIEM (Microsoft Azure Sentinel) - Needs visibility to every single system that needs to be monitored, collects and correlates data/events from other systems, used for forensic analysis in incident investigations. Rapid 7 - Vulnerability management system that scans the network and identifies servers and other assets. - Veracode - Application security system / software development lifecycle system. Used for securing code at the GitHub level for current and future releases. | K10: Security Assurance - Proactive activities including cybersecurity awareness, certification management, program management, and risk management. Ensures controls for cybersecurity exist in the bank's infrastructure and applications. Includes Security Governance (Policies, Procedures, Processes, Baselines, Standards), Information Security Awareness (User training and testing), ISMS Continuous Improvement, Risk Management (CRA, Risk Register, Exception Management), Internal Controls Framework, and Capital Projects Administration. Security engineering and architecture - Design and review of applications and systems to ensure they are designed and correctly controlled. Ensuring secure software development lifecycle. Includes Application Security (SDLC security: DAST/SAST, Developer security awareness, Security Champions Program), Security Accreditations, Cloud and Network Security Architecture, API Architecture Security, and Cloud Security Posture Management. Security operations - Monitor, detect, and respond to incidents, vulnerability and compliance, security testing. Operates security tools. Follows information security incident response plan. Includes Security Tools Operation (R7, Burp, Defender, Sentinel, ...), Vulnerability & Compliance Management (On prem, Cloud, SaaS, Websites), Cyber Threat Intelligence, Endpoint Detection, SIEM (monitoring and correlation), Incident Response and Escalation, Digital Forensics, eDiscovery, Security Operation Center, and Security Testing (Password Testing, Penetration Testing, Tabletops). ISMS Operation – ISO27K certification Security Awareness Training Security Awareness Testing/ Phishing Audit management KPIs & Indicators Security Engineering Design Secure Code/DevSecOps* Developers Security Training (Security Champions) Cloud Security and Architecture* Application Security Reviews or Accreditations (PRACs) Cloud Risk Assessments (CRA) API Security Vulnerability Management (Servers, Cloud, Infrastructure) Internal and External Pen-testing / Red Team / Tabletop Threat Intelligence* Detection and Monitoring Incident Response * Baseline Compliance testing Security Tool Management (Security Certificates, Endpoint security, Networking, etc) | L10: =IF(ISBLANK(H10),"No","Yes") -> No | M10: =IF(OR(COUNTIF('Finance & Enterprise'!D:D,A10)>0,COUNTIF(Operations!E:E,A10)>0,COUNTIF(Enablers!D:D,A10)>0),"Yes","No") -> Yes
A11: Data Management | B11: Technology and Data Solutions | C11: The Data Management enabler is responsible for ensuring that data is treated as a strategic asset across the organization. It encompasses end-to-end data capabilities, including database administration, data architecture, and the design and operation of modern data platforms. This enabler supports data analytics products and the Data Marketplace to enable business insights and data-driven decision-making. It also implements data governance and quality solutions to ensure accuracy, consistency, security, and compliance across all data assets, providing a trusted foundation for digital transformation. This enabler also support the pubication of open data assets of the bank with the world and provide a strategic architecture for external solutions such as the site of the bank. | D11: Enabler | E11: https://iadb-ttd.atlassian.net/jira/software/c/projects/DMP/boards/55 | F11: Data-Driven Culture and Continuous Improvements Secure First, Secure Always Technology Modernization and Efficiency Improvements Knowledge Bank Data Literacy of the Bank | G11: carlosd@iadb.org | I11: High-quality data services that support decision-making, operational efficiency, and strategic initiatives through governed, accessible, and reliable data solutions. | J11: Convergence - Operational data TMS - Treasury data SAP - HR, Budget and Accounting LFM - Financial data EntraID - Security and authentication AWS StepFunctions CKAN PowerBI ESRI ArcGIS AWS SageMaker Informatica (DI, DQ, DG) AWS Lambda AWS Glue AWS Athena OneTrust SAP SLT MS PowerAutomate Azure Automation Account MS PowerAutomate AWS Redshift Microsoft SQL Oracle AWS S3 AWS Dynamo Azure Storage Account AWS RDS AWS Lakeformation Cyberark AWS SecretsManager AWS SNS AWS CloudWatch AWS EventBridge AWS CloudFormation AWS IAM AWS KMS AWS EC2 MS EntraID / Active Directory | K11: Data Management: data integration, certification and publication for consumption and support the decision making process. Database administration: Manage and maintain databases Data Analytics Products: support of the core analytical tools used to visualize data in various ways. Data Marketplace: catalog and publication of certified data assets. Data Architecture: Design and structure data systems for transactional applications (currently lacking) Data services: Access to Data via APIs For product/system consumption Consultancy: Data-related advisory services Data Governance & Quality Solutions: Data quality, privacy, and governance services Business Intelligence & Analytics : Reports and dashboards for institutional/business use Data Integration & Cataloging: Data marketplace, ETL, and metadata management Open Data: support of the technological platforms and publication process of open and public data. | L11: =IF(ISBLANK(H11),"No","Yes") -> No | M11: =IF(OR(COUNTIF('Finance & Enterprise'!D:D,A11)>0,COUNTIF(Operations!E:E,A11)>0,COUNTIF(Enablers!D:D,A11)>0),"Yes","No") -> Yes
A12: Development Assets | B12: Enterprise and Finance | C12: The Development Assets products provides a centralized, integrated view and financial support for loans, equity investments, and guarantees—empowering finance teams in servicing, accounting, and client management while enabling the entire bank to understand, track, and connect all related systems and financial assets efficiently. | D12: Product | E12: https://iadb-ttd.atlassian.net/jira/software/c/projects/DA/boards/245 | F12: One of the main goals of the IDB Impact Plus strategy is to enhance efficiency, transparency, and strategic decision-making through integrated and centralized management of financial assets such as loans, guarantees, and equities. Providing flexible solutions to adapt to new financial products. Strengthen IDB financial capacity and enables support for innovative financial solutions, disaster risk management related financial products, and more. Strengthen IDB competitiveness in the region | G12: MMAGARINOS@IADB.ORG | I12: The IDB requires centralized, accurate, and timely management into the financial status of loans, equities, and guarantees to prevent accounting errors, reduce operational risks, and ensure informed decision-making based on complete and reliable data. | J12: Maestro (IDB invest system) - manage and synchronize the operational and financial lifecycle loan including items such us sugnatures, eligibility and disbursements Cash / Quantum - support cash dusburments collections Bloomberg (external) - interest rates ECP (external client portal) - provide access to ur bills, rate notifications and request loan balance confirmation ezShare - publishing and retrival of documents EDW - provide data for reporting for all bank usage | K12: Servicing - Support disbursement processing, billing, collections Accounting - Support contract onboarding, financial terms, loan re-structures, contract closure, GL reconciliations Reporting - Calculators for external purposes, notifications, data for bank consumption. | L12: =IF(ISBLANK(H12),"No","Yes") -> No | M12: =IF(OR(COUNTIF('Finance & Enterprise'!D:D,A12)>0,COUNTIF(Operations!E:E,A12)>0,COUNTIF(Enablers!D:D,A12)>0),"Yes","No") -> Yes
A13: Digital Strengthening for Operations | B13: Technology and Transformation in the Region | C13: Strengthen IDB Impact by fostering collaboration between TTD/TTR and VPS Operations Teams, streamlining tools and support throughout the operation lifecycle and the effective design and implementation of an information security strategy, policies, and controls for operations and digital solutions deployed in these operations. | D13: Product | E13: Pending | F13: Bolstering Sustainable Regional Growth: by providing the digital infrastructure needed to accelerate innovation, strengthen institutional capacity, and enhance the delivery of public services. Reduce Poverty and Inequality: by enabling governments and institutions to quickly deploy digital tools that improve the delivery of public services in areas such as education, health, food security, and gender equality. This product is part of the same product family as "Operational Innovation & Digital Advisory" and "Adoption and Experimentation Environments". The TTR Group's primary role is identifying opportunities for technology innovations in IDB projects. The goal is to create technological resources and services to assist operational teams in implementing Digital Solutions. | G13: GFRANCOA@iadb.org | I13: IDB Operational teams struggle with fragmented operations, inefficiencies, and a lack of synergies. Our product aims to break silos, promote/improve efficiencies, and foster synergies through governance, especially in the context of digital solutions. We help address the challenges faced during the initial project structuring and preparation phases, as well as the more technical execution phase where digital solutions are implemented. | J13: None | K13: Project Management - Project Management services for TTR internal projects. This function is shared across all products in the family. Advisor for acquisitions (due dilligence) - Providing cybersecurity advice and due diligence support for acquisitions related to digital solutions. This includes cybersecurity advisory for digital solutions in operations and implementation of information security standards in IDBCloud4LAC. Also acts as a cybersecurity assessor and advisor for investment prospects. Governance (standards) - Establishing standards and governance for digital solutions within TTD and for sectors, promoting a consistent way of working. Standardize internal processes in TTR and processes related to the creation of digital solutions in conjunction with sectors (operations team), communications (DCC), and any other party. Knowledge Sharing - Building a digital catalog of digital solutions from operations and lessons learned, allowing queries to find existing solutions. This focuses specifically on digital solutions, not general operational knowledge related to physical projects (e.g., bridges). Sourcing for the extended/external services - Sourcing people and resources to manage demand for extended services, as internal enablers or resources from other TTD products cannot always be used. This includes providing resources (e.g., enterprise/security architects, software engineers) to support all TTR products in the family, operations' digital solutions, and IDBCloud4LAC. | L13: =IF(ISBLANK(H13),"No","Yes") -> No | M13: =IF(OR(COUNTIF('Finance & Enterprise'!D:D,A13)>0,COUNTIF(Operations!E:E,A13)>0,COUNTIF(Enablers!D:D,A13)>0),"Yes","No") -> No
A14: Digital Transformation | B14: Innovation and Business Transformation | C14: Accelerating transformation process in different areas across the organization. | D14: Enabler | E14: Pending | F14: Helping deliver the reforms that have been set by institucional strategy Improvement processes and systems | G14: gperla@IADB.ORG | I14: Bringing greater agility process to coporateprocesses within IDB, trying to adress data redundancies, acelerating deployment of AI along operational cycle. | J14: N/A | K14: Process transformation Change management Digitalization | L14: =IF(ISBLANK(H14),"No","Yes") -> No | M14: =IF(OR(COUNTIF('Finance & Enterprise'!D:D,A14)>0,COUNTIF(Operations!E:E,A14)>0,COUNTIF(Enablers!D:D,A14)>0),"Yes","No") -> No
A15: Digital Transformation of Secretary | B15: Secretary | C15: Develop and maintain systems for the Office of the Secretary for the Executive Directors or the Board of Governors and for upper management. Plus we provide all the technology services related to our annual meetings, which is the largest event of the bank. | D15: Product | E15: Pending | F15: Enabling the work that needs to be done by the decision making bodies of the bank. | G15: HCOSTA@iadb.org | H15: NATALIASE@IADB.ORG | I15: IT solutions for the corporate governance. Providing all the technological infrastructure to solve all the needs of the corporate governance of the bank. | J15: ezShare - Documentation DENODO - Data Azure - Services (level of autonomy limitation) AWS - Cloud servers Amazon SES - SMTP client | K15: Translation services - Translation services Interpretation services - Interpretation services Services to the board (commities coordination, minutes production, agendas) - Commities coordination, minutes production, agendas Event services (coordination and audiovisual services, agenda, nominations) - Coordination and audiovisual services, agenda, nominations Access to information policy - Access to information policy Services to governors - Coordinating the annual, regional, committee meetings Technology services - Technology services | L15: =IF(ISBLANK(H15),"No","Yes") -> Yes | M15: =IF(OR(COUNTIF('Finance & Enterprise'!D:D,A15)>0,COUNTIF(Operations!E:E,A15)>0,COUNTIF(Enablers!D:D,A15)>0),"Yes","No") -> No
A16: Emerging Tech | B16: Technology and Transformation in the Region | C16: TechLab is the Inter-American Development Bank’s engine for emerging technologies. We provide a safe, agile, and collaborative space where sector specialists and operational teams can explore, experiment, and adopt cutting-edge solutions—from AI and blockchain to VR and quantum computing. | D16: Product | E16: Pending | F16: Deliver impact through operations using latest technologies in the most efficient way. Help with efficiency by presenting moments of decision-making that their knowledge helped, such as identifying when a technology like blockchain is an overkill, saving money and changing directions. Accelerate the development or the "killing" of ideas, helping to align expectations with the actual capabilities of the technology. Create internal capacity about new technologies through workshops, events, and experiments, raising knowledge and helping the organization move to new technologies. | G16: rcerrato@IADB.ORG | I16: The Inter-American Development Bank (IDB) faces increasing pressure to stay ahead of rapid technological change while ensuring that innovation efforts are aligned with operational needs and institutional goals. TechLab solves the problem of how to explore, test, and validate emerging technologies before scaling them into real-world applications. | J16: IDB Publication Website - To publish research and knowledge, using the same platform as other IDB sectors IDB Cloud - To host their own cloud tenant for the sandbox environment, requiring interaction with the cloud team. Sharepoint - For their website where they share information. | K16: Technological vigilance - looking at the market and looking what's going on in the research side of the technology Experimentation - sing technology to start and explore if it's a good fit for a product or idea. Sandbox - An experimentation safe environment for deploying pilots, MVPs, and demos, but not for sensitive data or production. Technological avareness - Conducting events, workshops, and sessions to disseminate knowledge, lessons learned, and insights about emerging technologies, often with IDB clients like central banks. Research - Launching papers and publications through the IDB publication website, often with the help of external staff augmentation. | L16: =IF(ISBLANK(H16),"No","Yes") -> No | M16: =IF(OR(COUNTIF('Finance & Enterprise'!D:D,A16)>0,COUNTIF(Operations!E:E,A16)>0,COUNTIF(Enablers!D:D,A16)>0),"Yes","No") -> No
