Workbook

Sheet 0. Read me
B1: AI Capability Model - provenance for review
C2: Where each capability definition came from, how strongly, and whether a reviewer can open the source and check it.
C3: Companion to AI-Capability-Taxonomy-for-review.xlsx. That workbook asks whether the capability is right. This one asks whether we can prove where it came from.
B5: What changed before you got this
B6: Every source was re-verified | C6: Publisher, edition, date, URL and access were checked on 3 September 2026. That check found eighteen problems, all on sheet 3. Four are serious enough to block publication.
B7: The worst of them | C7: We cited EDM Council ADAC four times. It is a workgroup, not a publication - there is nothing to open. We cited TOGAF capability-based planning, which The Open Group deliberately removed from the 10th Edition. And four capabilities rest on Gartner or unattributed consultancy patterns, neither of which can appear in anything that leaves the Bank.
B8: 50 citation strings, 40 sources | C8: The model carried inconsistent variants - IBM GenAI vs IBM Generative AI, NIST AI RMF vs NIST AI RMF - Map. They are now one canonical source each, with the part of the source recorded separately.
B10: How to use it
B11: Sheet 1 - Source register | C11: One row per source. Read the Grade and Caution columns first. Grade D means it cannot be used as evidence outside the Bank.
B12: Sheet 2 - Capability to source | C12: One row per capability-source pair. Column G is the specific part of the source the capability rests on; column H says how much to trust that.
B13: Sheet 3 - Findings | C13: The eighteen problems, with what to do about each. Column I is yours.
B14: Sheet 4 - Scales | C14: What the derivation types and evidence grades mean. Read once.
B15: Sheet 5 - Coverage | C15: How the evidence base looks by domain. Where the thin spots are.
B17: The one thing to be careful about
B18: Candidate loci are unverified | C18: Column G on sheet 2 is my best reading of which part of each source a capability rests on. None of it is checked against the source text, and eleven sources are paywalled or members-only, so I could not check them. Treat column G as a work instruction, not a finding.
B19: What honest looks like here | C19: A capability that never gets its locus pinned should be reclassified Synthesized - assembled by us - rather than left claiming a source it cannot point into. That is a stronger position with Internal Audit than a citation that does not resolve.
B21: Counts
B22: Sources cited | C22: =COUNTA('1. Source register'!$A$2:$A$100)
B23: Capability-source pairs | C23: =COUNTA('2. Capability to source'!$A$2:$A$400)
B24: Pairs on grade A evidence | C24: =COUNTIF('2. Capability to source'!$J$2:$J$400,"A")
B25: Pairs on grade D - unusable externally | C25: =COUNTIF('2. Capability to source'!$J$2:$J$400,"D")
B26: Pairs with no locus at all | C26: =COUNTIF('2. Capability to source'!$H$2:$H$400,"NOT PINNED")
B27: Findings to clear | C27: =COUNTA('3. Findings'!$A$2:$A$60)

Sheet 1. Source register
A1: ID | B1: Short name | C1: Canonical title | D1: Publisher | E1: Edition / version | F1: Date | G1: URL | H1: Access | I1: Type | J1: What a valid citation looks like | K1: Grade | L1: Status | M1: Caution | N1: Times cited | O1: Your decision | P1: Your notes
A2: S01 | B2: ISO/IEC 42001 | C2: Information technology — Artificial intelligence — Management system | D2: ISO / IEC (JTC 1/SC 42) | E2: First edition | F2: 2023-12 | G2: https://www.iso.org/standard/42001 | H2: Paid — CHF 225; free contents preview | I2: Management system standard | J2: Clause number (e.g. 8.2) or Annex A control (e.g. A.5) | K2: C | L2: Current | M2: Paywalled: a reviewer without a licence cannot open it. EN ISO/IEC 42001:2026 is an identical European adoption, not a new edition. | N2: 14
A3: S02 | B3: ISO/IEC 5338 | C3: Information technology — Artificial intelligence — AI system life cycle processes | D3: ISO / IEC (JTC 1/SC 42) | E3: First edition | F3: 2023-12 | G3: https://www.iso.org/standard/81118.html | H3: Paid | I3: Process standard | J3: Clause 6 process id (e.g. 6.4.8 AI data engineering) | K3: C | L3: Current | M3: Paywalled. 6.4.7 Knowledge acquisition, 6.4.8 AI data engineering and 6.4.14 Continuous validation are the AI-specific additions over ISO/IEC/IEEE 15288. | N3: 9
A4: S03 | B4: ISO/IEC 38507 | C4: Information technology — Governance of IT — Governance implications of the use of artificial intelligence by organizations | D4: ISO / IEC (JTC 1/SC 40) | E4: First edition | F4: 2022-04 | G4: https://www.iso.org/standard/56641.html | H4: Paid | I4: Governance standard | J4: Clause number (e.g. 6.3 Governance of decision-making) | K4: C | L4: Current | M4: Paywalled. Our earlier short title paraphrased it — the canonical wording is 'by organizations', not 'for organizations'. | N4: 3
A5: S04 | B5: ISO/IEC 23894 | C5: Information technology — Artificial intelligence — Guidance on risk management | D5: ISO / IEC (JTC 1/SC 42) | E5: First edition | F5: 2023-02 | G5: https://www.iso.org/standard/77304.html | H5: Paid — CHF 155 | I5: Guidance standard | J5: Clause number (e.g. 6.4 Risk assessment) | K5: C | L5: Current | M5: Paywalled. Structure mirrors ISO 31000. | N5: 2
A6: S05 | B6: ISO/IEC 42005 | C6: Information technology — Artificial intelligence (AI) — AI system impact assessment | D6: ISO / IEC (JTC 1/SC 42) | E6: First edition | F6: 2025-05 | G6: https://www.iso.org/standard/42005 | H6: Paid — CHF 181 | I6: Guidance standard | J6: Clause number (e.g. 5.7 Establishing thresholds for sensitive uses) | K6: C | L6: Current | M6: Paywalled. Annex A gives the bridge to ISO/IEC 42001. | N6: 2
A7: S06 | B7: ISO/IEC 27001 | C7: Information security, cybersecurity and privacy protection — Information security management systems — Requirements | D7: ISO / IEC (JTC 1/SC 27) | E7: Third edition + Amd 1:2024 | F7: 2022-10 / 2024 | G7: https://www.iso.org/standard/27001 | H7: Paid — CHF 155; the 2024 climate amendment is free | I7: Management system standard | J7: Clause number or Annex A control (A.5 / A.6 / A.7 / A.8) | K7: C | L7: Current | M7: Paywalled. The 2022 edition renamed Annex A to 'Information security controls reference' — the 2013 wording no longer applies. | N7: 2
A8: S07 | B8: ISO/IEC 27701 | C8: Information security, cybersecurity and privacy protection — Privacy information management systems — Requirements and guidance | D8: ISO / IEC (JTC 1/SC 27) | E8: Second edition | F8: 2025-10 | G8: https://www.iso.org/standard/27701 | H8: Paid — CHF 225 | I8: Management system standard | J8: Clause number (e.g. 8.2 Privacy risk assessment) or Annex A control | K8: C | L8: Restructured — old loci invalid | M8: The 2025 second edition is a standalone management system standard; ISO/IEC 27701:2019 is withdrawn and its clause references no longer resolve. Annex F carries the correspondence. | N8: 1
A9: S08 | B9: NIST AI RMF | C9: Artificial Intelligence Risk Management Framework (AI RMF 1.0) | D9: NIST, U.S. Department of Commerce | E9: NIST AI 100-1, Version 1.0 | F9: 2023-01-26 | G9: https://nvlpubs.nist.gov/nistpubs/ai/NIST.AI.100-1.pdf | H9: Free — no registration | I9: Risk management framework | J9: Function, space, category.subcategory — e.g. GOVERN 1.1. NOT hyphenated | K9: A | L9: Current | M9: The hyphenated form GOVERN-1.1 is wrong; that convention belongs to AI 600-1 action ids (GV-1.1-001). Do not mix the two. | N9: 8
A10: S09 | B10: NIST AI 600-1 | C10: Artificial Intelligence Risk Management Framework: Generative Artificial Intelligence Profile | D10: NIST, U.S. Department of Commerce | E10: NIST AI 600-1 | F10: 2024-07-26 | G10: https://nvlpubs.nist.gov/nistpubs/ai/NIST.AI.600-1.pdf | H10: Free — no registration | I10: Profile of S08 | J10: Named risk from clause 2 (e.g. Confabulation) or action id (e.g. GV-1.1-001) | K10: A | L10: Current | M10: A cross-sectoral profile of the AI RMF, not a standalone framework — always cite alongside S08. | N10: 4
A11: S10 | B11: OECD AI Principles | C11: Recommendation of the Council on Artificial Intelligence (OECD/LEGAL/0449) | D11: OECD | E11: Adopted 2019; amended 2023-11 and 2024-05 | F11: 2024-05-03 | G11: https://legalinstruments.oecd.org/en/instruments/OECD-LEGAL-0449 | H11: Free | I11: Intergovernmental recommendation | J11: Section.Principle with trailing period — e.g. 1.3. | K11: A | L11: Current | M11: Cite the amended text. Principle 1.2 was retitled in 2024 — the 2019 name 'Human-centred values and fairness' is stale. Section 2 items are recommendations to adherents, not principles. | N11: 3
A12: S11 | B12: GAO AI Accountability Framework | C12: Artificial Intelligence: An Accountability Framework for Federal Agencies and Other Entities | D12: U.S. Government Accountability Office | E12: GAO-21-519SP | F12: 2021-06-30 | G12: https://www.gao.gov/assets/gao-21-519sp.pdf | H12: Free | I12: Accountability framework | J12: Principle name (Governance / Data / Performance / Monitoring) plus the key practice wording | K12: A | L12: Current | M12: GAO uses no numbered clause identifiers, so a locus is a principle name plus practice text. GAO-23-106811 is testimony summarising this, not a replacement. | N12: 5
A13: S12 | B13: AWS CAF-AI | C13: AWS Cloud Adoption Framework for Artificial Intelligence, Machine Learning, and Generative AI | D13: Amazon Web Services | E13: Whitepaper | F13: 2024-02-13 | G13: https://docs.aws.amazon.com/whitepapers/latest/aws-caf-for-ai/aws-caf-for-ai.html | H13: Free | I13: Capability model + adoption playbook | J13: Perspective name (Business / People / Governance / Platform / Security / Operations) plus capability name | K13: C | L13: Flagged historical by AWS | M13: AWS now displays 'This whitepaper is for historical reference only.' Cite it as a February 2024 artifact and say so. It is our most-used vendor capability source. | N13: 11
... A41: S39 | B41: IDB internal audit standards | C41: IDB internal audit standards | D41: Inter-American Development Bank | E41: n/a | F41: n/a | G41: Internal | H41: Internal | I41: Institutional policy | J41: Name the instrument and clause | K41: D | L41: Needs pinning | M41: Internal Audit to confirm which standards are relied on and whether the IIA Global Internal Audit Standards (2024) are adopted directly. | N41: 1

Sheet 2. Capability to source
A1: Domain | B1: Capability | C1: Capability name | D1: Source ID | E1: Source | F1: As cited in the model today | G1: Candidate locus (UNVERIFIED) | H1: Locus status | I1: Derivation | J1: Grade | K1: Source status | L1: Access | M1: Your decision | N1: Corrected locus | O1: Your notes
A2: D1 | B2: 1.1 | C2: AI Vision & Strategy Definition | D2: S12 | E2: AWS CAF-AI | F2: AWS CAF-AI - Business perspective | G2: Business perspective | H2: stated in our own citation | I2: Adapted | J2: C | K2: Flagged historical by AWS | L2: Free
A3: D1 | B3: 1.1 | C3: AI Vision & Strategy Definition | D3: S03 | E3: ISO/IEC 38507 | F3: ISO/IEC 38507 | G3: 6.2 Governance oversight of AI | H3: candidate - unverified | I3: Corroborating | J3: C | K3: Current | L3: Paid
A4: D1 | B4: 1.1 | C4: AI Vision & Strategy Definition | D4: S29 | E4: MITRE AI Maturity Model | F4: MITRE AI Maturity Model | G4: Strategy and Resources pillar | H4: candidate - unverified | I4: Corroborating | J4: B | K4: Ageing | L4: Free — guide only; assessment tool on request
A5: D1 | B5: 1.2 | C5: AI Portfolio & Investment Management | D5: S12 | E5: AWS CAF-AI | F5: AWS CAF-AI | G5: Business perspective | H5: candidate - unverified | I5: Adapted | J5: C | K5: Flagged historical by AWS | L5: Free
A6: D1 | B6: 1.2 | C6: AI Portfolio & Investment Management | D6: S34 | E6: Gartner | F6: Gartner (analyst, non-public) | H6: NOT PINNED | I6: Unsupported | J6: D | K6: Non-public | L6: Subscription — non-public
A7: D1 | B7: 1.2 | C7: AI Portfolio & Investment Management | D7: S21 | E7: TOGAF G193 Capability-Based Planning | F7: TOGAF (capability-based planning) | G7: G193 in full | H7: candidate - unverified | I7: Corroborating | J7: B | K7: Current | L7: Free for non-commercial after registration
A8: D1 | B8: 1.3 | C8: Value Realization & Performance Reporting | D8: S19 | E8: WEF AI-First Operating System | F8: WEF AI-First Operating System | G8: New value creation | H8: candidate - unverified | I8: Adapted | J8: B | K8: Current | L8: Free
A9: D1 | B9: 1.3 | C9: Value Realization & Performance Reporting | D9: S30 | E9: MIT CISR | F9: MIT CISR | G9: Stage 3 Develop AI Ways of Working | H9: candidate - unverified | I9: Corroborating | J9: B | K9: Current | L9: Readable on site; PDF requires login
A10: D1 | B10: 1.3 | C10: Value Realization & Performance Reporting | D10: S11 | E10: GAO AI Accountability Framework | F10: GAO AI Accountability Framework | G10: Governance principle - organizational level | H10: candidate - unverified | I10: Corroborating | J10: A | K10: Current | L10: Free
A11: D1 | B11: 1.4 | C11: AI Sourcing & Partner Strategy | D11: S01 | E11: ISO/IEC 42001 | F11: ISO/IEC 42001 - third-party control | G11: A.10 Third-party and customer relationships | H11: stated in our own citation | I11: Adapted | J11: C | K11: Current | L11: Paid — CHF 225; free contents preview
A12: D1 | B12: 1.4 | C12: AI Sourcing & Partner Strategy | D12: S12 | E12: AWS CAF-AI | F12: AWS CAF-AI | G12: Business perspective | H12: candidate - unverified | I12: Corroborating | J12: C | K12: Flagged historical by AWS | L12: Free
A13: D1 | B13: 1.5 | C13: AI Ecosystem & Alliance Management | D13: S01 | E13: ISO/IEC 42001 | F13: ISO/IEC 42001 - context and interested parties | G13: Clause 4 Context of the organization | H13: stated in our own citation | I13: Synthesized | J13: C | K13: Current | L13: Paid — CHF 225; free contents preview
A14: D1 | B14: 1.5 | C14: AI Ecosystem & Alliance Management | D14: S22 | E14: Open Agile Architecture | F14: The Open Group Open Agile Architecture | G14: Part 2 The Agile Enterprise | H14: candidate - unverified | I14: Synthesized | J14: B | K14: Current | L14: Free perpetual non-commercial licence; paid commercial
A15: D1 | B15: 1.5 | C15: AI Ecosystem & Alliance Management | D15: S36 | E15: IDB institutional practice | F15: Institutional practice | H15: NOT PINNED | I15: Institutional | J15: D | K15: Needs a named internal document | L15: Internal
A16: D2 | B16: 2.1 | C16: Use Case Discovery & Intake | D16: S12 | E16: AWS CAF-AI | F16: AWS CAF-AI | G16: Business perspective | H16: candidate - unverified | I16: Adapted | J16: C | K16: Flagged historical by AWS | L16: Free
A17: D2 | B17: 2.1 | C17: Use Case Discovery & Intake | D17: S14 | E17: Google AI Adoption Framework | F17: Google AI Adoption Framework | G17: Lead theme | H17: candidate - unverified | I17: Corroborating | J17: C | K17: Undated, pre-GenAI | L17: Free
A18: D2 | B18: 2.2 | C18: AI Use-Case Feasibility & Qualification | D18: S15 | E18: IBM GenAI Capability Model | F18: IBM Generative AI Capability Model | G18: Supporting Capabilities | H18: candidate - unverified | I18: Adapted | J18: B | K18: Current | L18: Free
A19: D2 | B19: 2.2 | C19: AI Use-Case Feasibility & Qualification | D19: S12 | E19: AWS CAF-AI | F19: AWS CAF-AI - Business perspective | G19: Business perspective | H19: stated in our own citation | I19: Corroborating | J19: C | K19: Flagged historical by AWS | L19: Free
A20: D2 | B20: 2.2 | C20: AI Use-Case Feasibility & Qualification | D20: S20 | E20: TOGAF Standard | F20: The Open Group TOGAF | H20: NOT PINNED | I20: Corroborating | J20: B | K20: Current | L20: Free for non-commercial after registration; paid for commercial
A21: D2 | B21: 2.3 | C21: AI Product Management | D21: S19 | E21: WEF AI-First Operating System | F21: WEF AI-First Operating System | G21: Operations redesign | H21: candidate - unverified | I21: Adapted | J21: B | K21: Current | L21: Free
A22: D2 | B22: 2.3 | C22: AI Product Management | D22: S23 | E22: IT4IT Standard | F22: The Open Group IT4IT | G22: Explore value stream | H22: candidate - unverified | I22: Corroborating | J22: B | K22: Current | L22: Free to read
A23: D2 | B23: 2.3 | C23: AI Product Management | D23: S22 | E23: Open Agile Architecture | F23: The Open Group Open Agile Architecture | G23: Part 2 The Agile Enterprise | H23: candidate - unverified | I23: Corroborating | J23: B | K23: Current | L23: Free perpetual non-commercial licence; paid commercial
A24: D2 | B24: 2.4 | C24: Business Process & Service Redesign | D24: S19 | E24: WEF AI-First Operating System | F24: WEF AI-First Operating System | G24: Operations redesign | H24: candidate - unverified | I24: Adapted | J24: B | K24: Current | L24: Free
A25: D2 | B25: 2.4 | C25: Business Process & Service Redesign | D25: S35 | E25: Consultancy transformation patterns | F25: Consultancy transformation patterns (non-public) | H25: NOT PINNED | I25: Unsupported | J25: D | K25: Not a publication | L25: Non-public
A26: D2 | B26: 2.4 | C26: Business Process & Service Redesign | D26: S22 | E26: Open Agile Architecture | F26: The Open Group Open Agile Architecture | G26: Part 2 The Agile Enterprise | H26: candidate - unverified | I26: Corroborating | J26: B | K26: Current | L26: Free perpetual non-commercial licence; paid commercial
A27: D2 | B27: 2.5 | C27: Human-AI Interaction & Oversight Design | D27: S31 | E27: IMDA Model AI Governance Framework | F27: IMDA Model AI Governance Framework | G27: Trusted Development and Deployment | H27: candidate - unverified | I27: Synthesized | J27: A | K27: Current — but our citation was ambiguous | L27: Free
A28: D2 | B28: 2.5 | C28: Human-AI Interaction & Oversight Design | D28: S01 | E28: ISO/IEC 42001 | F28: ISO/IEC 42001 | G28: A.6 AI system life cycle | H28: candidate - unverified | I28: Synthesized | J28: C | K28: Current | L28: Paid — CHF 225; free contents preview
A29: D2 | B29: 2.6 | C29: AI Innovation & Incubation | D29: S14 | E29: Google AI Adoption Framework | F29: Google AI Adoption Framework | G29: Lead theme | H29: candidate - unverified | I29: Synthesized | J29: C | K29: Undated, pre-GenAI | L29: Free
A30: D2 | B30: 2.6 | C30: AI Innovation & Incubation | D30: S12 | E30: AWS CAF-AI | F30: AWS CAF-AI | G30: Business perspective | H30: candidate - unverified | I30: Synthesized | J30: C | K30: Flagged historical by AWS | L30: Free
A31: D2 | B31: 2.6 | C31: AI Innovation & Incubation | D31: S36 | E31: IDB institutional practice | F31: Institutional practice | H31: NOT PINNED | I31: Institutional | J31: D | K31: Needs a named internal document | L31: Internal
A32: D3 | B32: 3.1 | C32: Data Governance & Stewardship for AI | D32: S25 | E32: EDM Council DCAM | F32: EDM Council DCAM/ADAC | G32: Data Quality Management; Govern Data & Data Management Program | H32: candidate - unverified | I32: Adapted | J32: C | K32: Current but members-only | L32: Members only
A33: D3 | B33: 3.1 | C33: Data Governance & Stewardship for AI | D33: S26 | E33: EDM Council ADAC | F33: EDM Council DCAM/ADAC (second artifact named in the same string) | H33: NOT PINNED | I33: Unsupported | J33: D | K33: Not a publication | L33: n/a
A34: D3 | B34: 3.1 | C34: Data Governance & Stewardship for AI | D34: S01 | E34: ISO/IEC 42001 | F34: ISO/IEC 42001 | G34: A.7 Data for AI systems | H34: candidate - unverified | I34: Corroborating | J34: C | K34: Current | L34: Paid — CHF 225; free contents preview
A35: D3 | B35: 3.2 | C35: Data Sourcing, Licensing & Provenance | D35: S08 | E35: NIST AI RMF | F35: NIST AI RMF - Map | G35: MAP | H35: stated in our own citation | I35: Adapted | J35: A | K35: Current | L35: Free — no registration
A36: D3 | B36: 3.2 | C36: Data Sourcing, Licensing & Provenance | D36: S25 | E36: EDM Council DCAM | F36: EDM Council DCAM/ADAC | G36: Data Quality Management; Govern Data & Data Management Program | H36: candidate - unverified | I36: Corroborating | J36: C | K36: Current but members-only | L36: Members only
A37: D3 | B37: 3.2 | C37: Data Sourcing, Licensing & Provenance | D37: S26 | E37: EDM Council ADAC | F37: EDM Council DCAM/ADAC (second artifact named in the same string) | H37: NOT PINNED | I37: Unsupported | J37: D | K37: Not a publication | L37: n/a
A38: D3 | B38: 3.3 | C38: Data Quality & Preparation for AI | D38: S02 | E38: ISO/IEC 5338 | F38: ISO/IEC 5338 | G38: 6.4.8 AI data engineering | H38: candidate - unverified | I38: Adapted | J38: C | K38: Current | L38: Paid
A39: D3 | B39: 3.3 | C39: Data Quality & Preparation for AI | D39: S25 | E39: EDM Council DCAM | F39: EDM Council DCAM/ADAC | G39: Data Quality Management; Govern Data & Data Management Program | H39: candidate - unverified | I39: Corroborating | J39: C | K39: Current but members-only | L39: Members only
A40: D3 | B40: 3.3 | C40: Data Quality & Preparation for AI | D40: S26 | E40: EDM Council ADAC | F40: EDM Council DCAM/ADAC (second artifact named in the same string) | H40: NOT PINNED | I40: Unsupported | J40: D | K40: Not a publication | L40: n/a
...

Sheet 3. Findings
A1: ID | B1: Finding | C1: Sources | D1: Capabilities affected | E1: Severity | F1: What we found | G1: Recommended action | H1: Your decision | I1: Your notes
A2: F01 | B2: EDM Council ADAC is not a publication | C2: S26 | D2: 3.1, 3.3, 3.4, 3.7 | E2: Critical | F2: ADAC (AI, Data & Analytics Controls) is an EDM Council workgroup, not a framework. It is absent from EDM Council's own Frameworks page; the visible output is webinars and a 2024 SIG deck. It was cited four times as if it were a document. | G2: Remove ADAC from all four capabilities. If an EDM Council AI/data-controls reference is needed, substitute CDMC, which is openly available for internal use.
A3: F02 | B3: TOGAF capability-based planning was removed from the current edition | C3: S21 | D3: 1.2 | E3: Critical | F3: Capability-Based Planning was Chapter 28 of TOGAF 9.2. The Open Group deliberately removed it in the 10th Edition because it is incompatible with the Business Capabilities Series Guide. Our citation pointed at a section that no longer exists. | G3: Re-cite as TOGAF Series Guide G193 (Capability-Based Planning) or G190 (Business Capabilities v2). Already reflected in the register as S21.
A4: F03 | B4: The IIA Three Lines Model we cited has been superseded | C4: S28 | D4: 7.8 | E4: High | F4: The 2020 position paper was replaced on 8 July 2026 by the Statement of Position 'Assurance and Advice in Support of Effective Governance'. It carries five principles, not six. 'Three Lines of Defense' is doubly retired. | G4: Cite the 2026 Statement of Position. Check any capability wording that assumed the six-principle structure.
A5: F04 | B5: ISO/IEC 27701:2019 clause references no longer resolve | C5: S07 | D5: 7.5 | E5: High | F5: The second edition (October 2025) converted 27701 from an extension of 27001/27002 into a standalone management system standard. The old PIMS-specific clause forms do not exist in it. | G5: Re-pin against the 2025 edition; Annex F carries the correspondence from the 2019 numbering.
A6: F05 | B6: ITIL 4 is no longer the current ITIL | C6: S24 | D6: 6.1, 6.4, 5.3 | E6: Medium | F6: ITIL Version 5 was announced in January 2026 and is rolling out; ITIL 4 remains valid in parallel through a transition period. | G6: Keep the ITIL 4 citation but add the qualifier. Do not describe ITIL 4 as current without it.
A7: F06 | B7: AWS flags CAF-AI as historical reference only | C7: S12 | D7: seven capabilities | E7: Medium | F7: AWS displays 'This whitepaper is for historical reference only. Some content might be outdated' on the CAF-AI page. It is our most-used vendor capability source. | G7: Keep it - it is still the best-structured public AI capability model - but cite it as a February 2024 artifact and disclose the banner rather than let a reviewer find it.
A8: F07 | B8: Our IMDA citation is ambiguous across three documents | C8: S31 | D8: five capabilities | E8: High | F8: Three published frameworks share the name: the original Model AI Governance Framework (2nd ed. 2020), the Generative AI framework (May 2024, nine dimensions) and the Agentic AI framework (v1.0, January 2026, four dimensions). We cited it unqualified. | G8: Pick one per capability. Agentic capabilities should point at the January 2026 agentic framework (added to the register as S31b).
A9: F08 | B9: MIT CISR is a research centre, not a document | C9: S30 | D9: 1.3 | E9: High | F9: 'MIT CISR' names no artifact. A citation has to name a Research Briefing or Working Paper with its volume and number. | G9: Substitute the August 2025 Research Briefing 'Grow Enterprise AI Maturity for Bottom-Line Impact' (Vol. XXV, No. 8), already in the register.
A10: F09 | B10: NIST AI RMF locus form | C10: S08 | D10: all NIST citations | E10: Medium | F10: The correct citation form is GOVERN 1.1 - function, space, category.subcategory. The hyphenated GOVERN-1.1 is not valid; that convention belongs to AI 600-1 action identifiers (GV-1.1-001). | G10: Use the space form throughout. Any hyphenated reference in draft text is wrong.
A11: F10 | B11: OECD principle 1.2 was retitled | C11: S10 | D11: 1.1, 7.2 | E11: Medium | F11: The Recommendation was amended in November 2023 and May 2024. Principle 1.2, cited widely under its 2019 name 'Human-centred values and fairness', is now 'Respect for the rule of law, human rights and democratic values, including fairness and privacy'. | G11: Cite the amended text and the current principle titles.
A12: F11 | B12: Non-public sources cannot carry evidence | C12: S34, S35 | D12: four capabilities | E12: Critical | F12: Gartner research is subscription-licensed - usable internally, not quotable in anything that circulates externally, and not openable by a reviewer without a seat. 'Consultancy transformation patterns' names nothing at all. | G12: Remove both from the published provenance. Where a capability rests only on them, find an open source or reclassify it as Synthesized and say so.
A13: F12 | B13: 'Institutional practice' names no document | C13: S36, S37, S38, S39 | D13: six capabilities | E13: High | F13: Institutional origin is legitimate, but 'institutional practice' is not a citation - a reviewer cannot open it, date it, or find its owner. | G13: Replace each use with a named internal policy, standard or procedure, with an owner and a date. Data Governance, Legal and Internal Audit each own one of these.
... A19: F18 | B19: Every candidate locus in this workbook is unverified | C19: all | D19: all | E19: High | F19: Column H of the mapping sheet is my best reading of which part of each source a capability rests on. None of it has been checked against the source text, and eleven of the sources are paywalled or members-only. | G19: Confirm or correct each one. A capability whose locus is never pinned should be downgraded to Synthesized rather than left claiming a source it cannot point into.

Sheet 4. Scales
B1: Derivation - how a capability relates to a source
B3: Adopted | C3: The source names this capability as a capability, and our wording follows it. Strongest claim - a reviewer can put the two side by side.
B4: Adapted | C4: The source names it, and we narrowed, renamed or re-scoped it for the institution. The commonest honest case.
B5: Corroborating | C5: The source did not originate the capability but independently supports that it belongs in the model. Never the only source on a row.
B6: Synthesized | C6: No single source names it. Assembled from two or more that each cover part of it - or from what the model demonstrably needs and nothing published yet covers.
B7: Institutional | C7: Derived from IDB policy or practice, not from any external source.
B8: Unsupported | C8: The cited source does not substantiate the capability. Must be removed or replaced before the model is published.
B11: Evidence grade - whether a reviewer can check it
B13: A | C13: Openly available, dated, versioned, from a standards body or public authority. A reviewer can open it today and find the cited part.
B14: B | C14: Openly available and dated, but vendor-published or non-normative. Verifiable, not authoritative.
B15: C | C15: Available but undated, superseded, flagged historical by its own publisher, or paywalled. A reviewer may not be able to check it.
B16: D | C16: Non-public, or not a publication at all. Cannot serve as evidence in anything that leaves the Bank.
B19: Locus status
B21: stated in our own citation | C21: The model already named the part of the source - e.g. "AWS CAF-AI - Business perspective". Still worth confirming, but it was a deliberate choice at the time.
B22: candidate - unverified | C22: I inferred which part of the source the capability rests on, from the source structure verified on 3 September 2026. Not checked against the text. Confirm or correct.
B23: NOT PINNED | C23: No candidate could be offered - usually because the source has no enumerable structure, or is one we cannot open. These need a decision, not a confirmation.

Sheet 5. Coverage
A1: Domain | B1: Domain name | C1: Capabilities | D1: Citations | E1: Citations on A | F1: Citations on B | G1: Citations on C | H1: Citations on D | I1: Citations not pinned | J1: Citations marked Synthesized | K1: Citations marked Unsupported
A2: D1 | B2: AI Strategy & Value Management | C2: 5 | D2: =COUNTIF('2. Capability to source'!$A$2:$A$400,$A2) | E2: =COUNTIFS('2. Capability to source'!$A$2:$A$400,$A2,'2. Capability to source'!$J$2:$J$400,"A") | F2: =COUNTIFS('2. Capability to source'!$A$2:$A$400,$A2,'2. Capability to source'!$J$2:$J$400,"B") | G2: =COUNTIFS('2. Capability to source'!$A$2:$A$400,$A2,'2. Capability to source'!$J$2:$J$400,"C") | H2: =COUNTIFS('2. Capability to source'!$A$2:$A$400,$A2,'2. Capability to source'!$J$2:$J$400,"D") | I2: =COUNTIFS('2. Capability to source'!$A$2:$A$400,$A2,'2. Capability to source'!$H$2:$H$400,"NOT PINNED") | J2: =COUNTIFS('2. Capability to source'!$A$2:$A$400,$A2,'2. Capability to source'!$I$2:$I$400,"Synthesized") | K2: =COUNTIFS('2. Capability to source'!$A$2:$A$400,$A2,'2. Capability to source'!$I$2:$I$400,"Unsupported")
A3: D2 | B3: AI Demand & Solution Shaping | C3: 6 | D3: =COUNTIF('2. Capability to source'!$A$2:$A$400,$A3) | E3: =COUNTIFS('2. Capability to source'!$A$2:$A$400,$A3,'2. Capability to source'!$J$2:$J$400,"A") | F3: =COUNTIFS('2. Capability to source'!$A$2:$A$400,$A3,'2. Capability to source'!$J$2:$J$400,"B") | G3: =COUNTIFS('2. Capability to source'!$A$2:$A$400,$A3,'2. Capability to source'!$J$2:$J$400,"C") | H3: =COUNTIFS('2. Capability to source'!$A$2:$A$400,$A3,'2. Capability to source'!$J$2:$J$400,"D") | I3: =COUNTIFS('2. Capability to source'!$A$2:$A$400,$A3,'2. Capability to source'!$H$2:$H$400,"NOT PINNED") | J3: =COUNTIFS('2. Capability to source'!$A$2:$A$400,$A3,'2. Capability to source'!$I$2:$I$400,"Synthesized") | K3: =COUNTIFS('2. Capability to source'!$A$2:$A$400,$A3,'2. Capability to source'!$I$2:$I$400,"Unsupported")
A4: D3 | B4: Data & Knowledge Management | C4: 7 | D4: =COUNTIF('2. Capability to source'!$A$2:$A$400,$A4) | E4: =COUNTIFS('2. Capability to source'!$A$2:$A$400,$A4,'2. Capability to source'!$J$2:$J$400,"A") | F4: =COUNTIFS('2. Capability to source'!$A$2:$A$400,$A4,'2. Capability to source'!$J$2:$J$400,"B") | G4: =COUNTIFS('2. Capability to source'!$A$2:$A$400,$A4,'2. Capability to source'!$J$2:$J$400,"C") | H4: =COUNTIFS('2. Capability to source'!$A$2:$A$400,$A4,'2. Capability to source'!$J$2:$J$400,"D") | I4: =COUNTIFS('2. Capability to source'!$A$2:$A$400,$A4,'2. Capability to source'!$H$2:$H$400,"NOT PINNED") | J4: =COUNTIFS('2. Capability to source'!$A$2:$A$400,$A4,'2. Capability to source'!$I$2:$I$400,"Synthesized") | K4: =COUNTIFS('2. Capability to source'!$A$2:$A$400,$A4,'2. Capability to source'!$I$2:$I$400,"Unsupported")
A5: D4 | B5: AI Solution Engineering | C5: 7 | D5: =COUNTIF('2. Capability to source'!$A$2:$A$400,$A5) | E5: =COUNTIFS('2. Capability to source'!$A$2:$A$400,$A5,'2. Capability to source'!$J$2:$J$400,"A") | F5: =COUNTIFS('2. Capability to source'!$A$2:$A$400,$A5,'2. Capability to source'!$J$2:$J$400,"B") | G5: =COUNTIFS('2. Capability to source'!$A$2:$A$400,$A5,'2. Capability to source'!$J$2:$J$400,"C") | H5: =COUNTIFS('2. Capability to source'!$A$2:$A$400,$A5,'2. Capability to source'!$J$2:$J$400,"D") | I5: =COUNTIFS('2. Capability to source'!$A$2:$A$400,$A5,'2. Capability to source'!$H$2:$H$400,"NOT PINNED") | J5: =COUNTIFS('2. Capability to source'!$A$2:$A$400,$A5,'2. Capability to source'!$I$2:$I$400,"Synthesized") | K5: =COUNTIFS('2. Capability to source'!$A$2:$A$400,$A5,'2. Capability to source'!$I$2:$I$400,"Unsupported")
A6: D5 | B6: AI Platform & Infrastructure | C6: 6 | D6: =COUNTIF('2. Capability to source'!$A$2:$A$400,$A6) | E6: =COUNTIFS('2. Capability to source'!$A$2:$A$400,$A6,'2. Capability to source'!$J$2:$J$400,"A") | F6: =COUNTIFS('2. Capability to source'!$A$2:$A$400,$A6,'2. Capability to source'!$J$2:$J$400,"B") | G6: =COUNTIFS('2. Capability to source'!$A$2:$A$400,$A6,'2. Capability to source'!$J$2:$J$400,"C") | H6: =COUNTIFS('2. Capability to source'!$A$2:$A$400,$A6,'2. Capability to source'!$J$2:$J$400,"D") | I6: =COUNTIFS('2. Capability to source'!$A$2:$A$400,$A6,'2. Capability to source'!$H$2:$H$400,"NOT PINNED") | J6: =COUNTIFS('2. Capability to source'!$A$2:$A$400,$A6,'2. Capability to source'!$I$2:$I$400,"Synthesized") | K6: =COUNTIFS('2. Capability to source'!$A$2:$A$400,$A6,'2. Capability to source'!$I$2:$I$400,"Unsupported")
A7: D6 | B7: AI Operations & Reliability | C7: 6 | D7: =COUNTIF('2. Capability to source'!$A$2:$A$400,$A7) | E7: =COUNTIFS('2. Capability to source'!$A$2:$A$400,$A7,'2. Capability to source'!$J$2:$J$400,"A") | F7: =COUNTIFS('2. Capability to source'!$A$2:$A$400,$A7,'2. Capability to source'!$J$2:$J$400,"B") | G7: =COUNTIFS('2. Capability to source'!$A$2:$A$400,$A7,'2. Capability to source'!$J$2:$J$400,"C") | H7: =COUNTIFS('2. Capability to source'!$A$2:$A$400,$A7,'2. Capability to source'!$J$2:$J$400,"D") | I7: =COUNTIFS('2. Capability to source'!$A$2:$A$400,$A7,'2. Capability to source'!$H$2:$H$400,"NOT PINNED") | J7: =COUNTIFS('2. Capability to source'!$A$2:$A$400,$A7,'2. Capability to source'!$I$2:$I$400,"Synthesized") | K7: =COUNTIFS('2. Capability to source'!$A$2:$A$400,$A7,'2. Capability to source'!$I$2:$I$400,"Unsupported")
A8: D7 | B8: AI Governance, Risk, Security & Assurance | C8: 9 | D8: =COUNTIF('2. Capability to source'!$A$2:$A$400,$A8) | E8: =COUNTIFS('2. Capability to source'!$A$2:$A$400,$A8,'2. Capability to source'!$J$2:$J$400,"A") | F8: =COUNTIFS('2. Capability to source'!$A$2:$A$400,$A8,'2. Capability to source'!$J$2:$J$400,"B") | G8: =COUNTIFS('2. Capability to source'!$A$2:$A$400,$A8,'2. Capability to source'!$J$2:$J$400,"C") | H8: =COUNTIFS('2. Capability to source'!$A$2:$A$400,$A8,'2. Capability to source'!$J$2:$J$400,"D") | I8: =COUNTIFS('2. Capability to source'!$A$2:$A$400,$A8,'2. Capability to source'!$H$2:$H$400,"NOT PINNED") | J8: =COUNTIFS('2. Capability to source'!$A$2:$A$400,$A8,'2. Capability to source'!$I$2:$I$400,"Synthesized") | K8: =COUNTIFS('2. Capability to source'!$A$2:$A$400,$A8,'2. Capability to source'!$I$2:$I$400,"Unsupported")
A9: D8 | B9: AI People, Skills & Adoption | C9: 6 | D9: =COUNTIF('2. Capability to source'!$A$2:$A$400,$A9) | E9: =COUNTIFS('2. Capability to source'!$A$2:$A$400,$A9,'2. Capability to source'!$J$2:$J$400,"A") | F9: =COUNTIFS('2. Capability to source'!$A$2:$A$400,$A9,'2. Capability to source'!$J$2:$J$400,"B") | G9: =COUNTIFS('2. Capability to source'!$A$2:$A$400,$A9,'2. Capability to source'!$J$2:$J$400,"C") | H9: =COUNTIFS('2. Capability to source'!$A$2:$A$400,$A9,'2. Capability to source'!$J$2:$J$400,"D") | I9: =COUNTIFS('2. Capability to source'!$A$2:$A$400,$A9,'2. Capability to source'!$H$2:$H$400,"NOT PINNED") | J9: =COUNTIFS('2. Capability to source'!$A$2:$A$400,$A9,'2. Capability to source'!$I$2:$I$400,"Synthesized") | K9: =COUNTIFS('2. Capability to source'!$A$2:$A$400,$A9,'2. Capability to source'!$I$2:$I$400,"Unsupported")
B10: Total | C10: =SUM(C2:C9) | D10: =SUM(D2:D9) | E10: =SUM(E2:E9) | F10: =SUM(F2:F9) | G10: =SUM(G2:G9) | H10: =SUM(H2:H9) | I10: =SUM(I2:I9) | J10: =SUM(J2:J9) | K10: =SUM(K2:K9)
B12: Read the D column and the Unsupported column first. A domain whose evidence sits mostly in C and D is not weakly assessed - it is unassessable by anyone outside the Bank, which is a different and worse problem. D7 is the domain where that matters most, because it is the one Internal Audit will open first.
