Workbook

Sheet 0. Read me
B1: Enterprise AI Capability Model
B2: Realization & Readiness · v0.5 · 52 capabilities · 258 criteria · 143 catalog entries
B4: The one rule that keeps this model honest
B5: Two scales, never merged | C5: A CAPABILITY carries MATURITY: is the institution able to do this, to what standard, with what evidence? A REALIZATION carries READINESS: has the enterprise packaged this well enough to consume? They measure different things and are never combined into a single number.
B6: The gap is the finding | C6: A capability can be readiness 4 and maturity 2 - the product is well packaged and the institution still cannot do the thing to the standard it needs. That combination is common, and it is invisible to any model carrying only one number.
B7: Never do this | C7: Never write a readiness level into the capability catalog. 'Semantic retrieval: readiness 4 via Azure AI Search' is a true statement about SUPPLY that silently substitutes for the maturity question. Both numbers or neither.
B9: Three catalogs
B10: 1 · Capability | C10: One row per L2 capability. Maturity, owner, target. No products, nothing below L2, no readiness.
B11: 2 · Realization | C11: One row per capability x pattern x technology. Readiness, consumption model, status, preferred. This is where the architecture goes.
B12: 3 · Enablement | C12: One row per realization x control. Evidence ticks. Replaces argument about whether a capability is 'had' with a list of things that either exist or do not.
B14: Grain - the mistake to avoid
B15: Sheet 1 rows are L2 | C15: Semantic retrieval, lexical retrieval and retrieval ranking are CATALOG entries (S3.2, S3.1, S3.4), not capabilities: they share an owner and fail the one-owner test. Put them in sheet 1 and the catalog grows from 50 rows to several hundred.
B17: Cell conventions
B18: Yellow fill, blue bold | C18: Your input. The only cells to edit.
B19: Black | C19: Fixed reference content. Changing it breaks the link to the published model.
B20: Green | C20: Formula, linked from another sheet.
B22: What is not done yet
B23: Rubrics | C23: One worked rubric exists (sheet 11). Until a capability has one, its maturity rating is provisional and must be labelled so.
B24: Control mapping | C24: ISO/IEC 42001 Annex A and NIST AI RMF outcomes are not mapped onto capabilities. Carve D7 out of any approval request until they are.
B25: Anchors | C25: New / Specialization / Lens are hypotheses with a confidence, unverified until the institution's existing capability map is crosswalked.
B26: Legal applicability | C26: Statutory references sit in sheet 10, all marked candidate. Nothing here asserts that any regulation binds the institution.

Sheet 1. Capability catalog
A1: Domain | B1: ID | C1: Capability | D1: Definition | E1: Accountable owner | F1: Anchor | G1: Conf. | H1: Agentic | I1: Criteria | J1: Criterion IDs | K1: MATURITY now | L1: MATURITY target | M1: Best readiness | N1: Gap: why maturity trails | O1: Evidence ref | P1: Notes
A2: D1 | B2: 1.1 | C2: AI Vision & Strategy Definition | D2: Able to establish and maintain a stated institutional position on AI and keep it current. | E2: Chief AI Officer | F2: New | G2: medium | I2: 5 | J2: 1.1.1 - 1.1.5 | M2: =IF(COUNTIF('2. Realization catalog'!$B$2:$B$500,$B2)=0,"",SUMPRODUCT(MAX(('2. Realization catalog'!$B$2:$B$500=$B2)*('2. Realization catalog'!$H$2:$H$500))))
A3: D1 | B3: 1.2 | C3: AI Portfolio & Investment Management | D3: Able to decide which AI work is funded, in what order, and when it stops. | E3: Enterprise Portfolio Owner | F3: Lens - keep existing node | G3: high | I3: 5 | J3: 1.2.1 - 1.2.5 | M3: =IF(COUNTIF('2. Realization catalog'!$B$2:$B$500,$B3)=0,"",SUMPRODUCT(MAX(('2. Realization catalog'!$B$2:$B$500=$B3)*('2. Realization catalog'!$H$2:$H$500))))
A4: D1 | B4: 1.3 | C4: Value Realization & Performance Reporting | D4: Able to prove what AI actually delivered, to the standard a governing body accepts. | E4: Strategy Performance Owner | F4: Lens - keep existing node | G4: high | I4: 5 | J4: 1.3.1 - 1.3.5 | M4: =IF(COUNTIF('2. Realization catalog'!$B$2:$B$500,$B4)=0,"",SUMPRODUCT(MAX(('2. Realization catalog'!$B$2:$B$500=$B4)*('2. Realization catalog'!$H$2:$H$500))))
A5: D1 | B5: 1.4 | C5: AI Sourcing & Partner Strategy | D5: Able to decide what is built, bought or partnered, and to stay able to change that decision. | E5: Chief Procurement Officer | F5: Specialization | G5: medium | I5: 5 | J5: 1.4.1 - 1.4.5 | M5: =IF(COUNTIF('2. Realization catalog'!$B$2:$B$500,$B5)=0,"",SUMPRODUCT(MAX(('2. Realization catalog'!$B$2:$B$500=$B5)*('2. Realization catalog'!$H$2:$H$500))))
A6: D1 | B6: 1.5 | C6: AI Ecosystem & Alliance Management | D6: Able to hold external AI relationships that are not supplier contracts, and to stay operable when the ecosystem around them changes. | E6: Chief AI Officer | F6: New | G6: low | I6: 6 | J6: 1.5.1 - 1.5.6 | M6: =IF(COUNTIF('2. Realization catalog'!$B$2:$B$500,$B6)=0,"",SUMPRODUCT(MAX(('2. Realization catalog'!$B$2:$B$500=$B6)*('2. Realization catalog'!$H$2:$H$500))))
A7: D2 | B7: 2.1 | C7: Use Case Discovery & Intake | D7: Able to surface candidate AI work and admit it through one controlled front door. | E7: Demand Management Owner | F7: Lens - keep existing node | G7: high | I7: 4 | J7: 2.1.1 - 2.1.4 | M7: =IF(COUNTIF('2. Realization catalog'!$B$2:$B$500,$B7)=0,"",SUMPRODUCT(MAX(('2. Realization catalog'!$B$2:$B$500=$B7)*('2. Realization catalog'!$H$2:$H$500))))
A8: D2 | B8: 2.2 | C8: AI Use-Case Feasibility & Qualification | D8: Able to judge, before build, whether a use case is technically and operationally deliverable and worth doing. | E8: AI Product Owner | F8: New | G8: medium | I8: 4 | J8: 2.2.1 - 2.2.4 | M8: =IF(COUNTIF('2. Realization catalog'!$B$2:$B$500,$B8)=0,"",SUMPRODUCT(MAX(('2. Realization catalog'!$B$2:$B$500=$B8)*('2. Realization catalog'!$H$2:$H$500))))
A9: D2 | B9: 2.3 | C9: AI Product Management | D9: Able to own an AI capability as a product across its life, not as a project that ends. | E9: AI Product Owner | F9: Specialization | G9: medium | I9: 5 | J9: 2.3.1 - 2.3.5 | M9: =IF(COUNTIF('2. Realization catalog'!$B$2:$B$500,$B9)=0,"",SUMPRODUCT(MAX(('2. Realization catalog'!$B$2:$B$500=$B9)*('2. Realization catalog'!$H$2:$H$500))))
A10: D2 | B10: 2.4 | C10: Business Process & Service Redesign | D10: Able to change how work is actually done, not merely to add a model to an unchanged process. | E10: Business Process Owner | F10: Specialization | G10: medium | I10: 6 | J10: 2.4.1 - 2.4.6 | M10: =IF(COUNTIF('2. Realization catalog'!$B$2:$B$500,$B10)=0,"",SUMPRODUCT(MAX(('2. Realization catalog'!$B$2:$B$500=$B10)*('2. Realization catalog'!$H$2:$H$500))))
A11: D2 | B11: 2.5 | C11: Human-AI Interaction & Oversight Design | D11: Able to design the human's role in the system, rather than assert oversight in policy alone. | E11: Product Design Owner | F11: New | G11: low | H11: Yes | I11: 6 | J11: 2.5.1 - 2.5.6 | M11: =IF(COUNTIF('2. Realization catalog'!$B$2:$B$500,$B11)=0,"",SUMPRODUCT(MAX(('2. Realization catalog'!$B$2:$B$500=$B11)*('2. Realization catalog'!$H$2:$H$500))))
A12: D2 | B12: 2.6 | C12: AI Innovation & Incubation | D12: Able to turn an untested AI idea into evidence, and evidence into either a funded product or a cheap, recorded stop. | E12: AI CoE Owner | F12: New | G12: low | I12: 5 | J12: 2.6.1 - 2.6.5 | M12: =IF(COUNTIF('2. Realization catalog'!$B$2:$B$500,$B12)=0,"",SUMPRODUCT(MAX(('2. Realization catalog'!$B$2:$B$500=$B12)*('2. Realization catalog'!$H$2:$H$500))))
A13: D3 | B13: 3.1 | C13: Data Governance & Stewardship for AI | D13: Able to say who owns each data asset, who may use it, and under what conditions. | E13: Chief Data Officer | F13: Specialization | G13: high | I13: 5 | J13: 3.1.1 - 3.1.5 | M13: =IF(COUNTIF('2. Realization catalog'!$B$2:$B$500,$B13)=0,"",SUMPRODUCT(MAX(('2. Realization catalog'!$B$2:$B$500=$B13)*('2. Realization catalog'!$H$2:$H$500))))
A14: D3 | B14: 3.2 | C14: Data Sourcing, Licensing & Provenance | D14: Able to demonstrate lawful, documented origin for every dataset an AI system uses. | E14: Chief Data Officer | F14: Specialization | G14: high | I14: 5 | J14: 3.2.1 - 3.2.5 | M14: =IF(COUNTIF('2. Realization catalog'!$B$2:$B$500,$B14)=0,"",SUMPRODUCT(MAX(('2. Realization catalog'!$B$2:$B$500=$B14)*('2. Realization catalog'!$H$2:$H$500))))
A15: D3 | B15: 3.3 | C15: Data Quality & Preparation for AI | D15: Able to make data fit for the specific AI purpose and to prove it was fit. | E15: Data Product Owner | F15: Specialization | G15: medium | I15: 5 | J15: 3.3.1 - 3.3.5 | M15: =IF(COUNTIF('2. Realization catalog'!$B$2:$B$500,$B15)=0,"",SUMPRODUCT(MAX(('2. Realization catalog'!$B$2:$B$500=$B15)*('2. Realization catalog'!$H$2:$H$500))))
A16: D3 | B16: 3.4 | C16: Metadata, Lineage & Cataloging for AI | D16: Able to find data, understand what it means, and trace where it went. | E16: Data Governance Owner | F16: Specialization | G16: high | I16: 4 | J16: 3.4.1 - 3.4.4 | M16: =IF(COUNTIF('2. Realization catalog'!$B$2:$B$500,$B16)=0,"",SUMPRODUCT(MAX(('2. Realization catalog'!$B$2:$B$500=$B16)*('2. Realization catalog'!$H$2:$H$500))))
A17: D3 | B17: 3.5 | C17: Knowledge Corpus & Content Management | D17: Able to curate the document and content estate that grounded AI depends on. | E17: Knowledge Management Owner | F17: New | G17: medium | I17: 5 | J17: 3.5.1 - 3.5.5 | M17: =IF(COUNTIF('2. Realization catalog'!$B$2:$B$500,$B17)=0,"",SUMPRODUCT(MAX(('2. Realization catalog'!$B$2:$B$500=$B17)*('2. Realization catalog'!$H$2:$H$500))))
A18: D3 | B18: 3.6 | C18: Knowledge Access & Retrieval | D18: Able to return the right knowledge to the right requester, with its provenance intact. | E18: Knowledge Platform Owner | F18: New | G18: low | I18: 5 | J18: 3.6.1 - 3.6.5 | M18: =IF(COUNTIF('2. Realization catalog'!$B$2:$B$500,$B18)=0,"",SUMPRODUCT(MAX(('2. Realization catalog'!$B$2:$B$500=$B18)*('2. Realization catalog'!$H$2:$H$500))))
A19: D3 | B19: 3.7 | C19: Derived Representation Management | D19: Able to manage derived representations of data as governed assets in their own right. | E19: Data/ML Platform Owner | F19: New | G19: low | I19: 4 | J19: 3.7.1 - 3.7.4 | M19: =IF(COUNTIF('2. Realization catalog'!$B$2:$B$500,$B19)=0,"",SUMPRODUCT(MAX(('2. Realization catalog'!$B$2:$B$500=$B19)*('2. Realization catalog'!$H$2:$H$500))))
A20: D4 | B20: 4.1 | C20: AI Architecture Management & Solution Governance | D20: Able to set, steward and enforce the architecture that AI solutions are built to. | E20: Chief Enterprise Architect | F20: Lens - keep existing node | G20: medium | I20: 7 | J20: 4.1.1 - 4.1.7 | M20: =IF(COUNTIF('2. Realization catalog'!$B$2:$B$500,$B20)=0,"",SUMPRODUCT(MAX(('2. Realization catalog'!$B$2:$B$500=$B20)*('2. Realization catalog'!$H$2:$H$500))))
A21: D4 | B21: 4.2 | C21: Model Selection, Customization & Tuning | D21: Able to choose and adapt models on evidence, and to record what was done. | E21: AI Engineering Owner | F21: New | G21: medium | I21: 5 | J21: 4.2.1 - 4.2.5 | M21: =IF(COUNTIF('2. Realization catalog'!$B$2:$B$500,$B21)=0,"",SUMPRODUCT(MAX(('2. Realization catalog'!$B$2:$B$500=$B21)*('2. Realization catalog'!$H$2:$H$500))))
A22: D4 | B22: 4.3 | C22: Prompt & Context Engineering | D22: Able to treat prompts and context assembly as versioned, tested engineering artifacts. | E22: AI Engineering Owner | F22: New | G22: medium | H22: Yes | I22: 5 | J22: 4.3.1 - 4.3.5 | M22: =IF(COUNTIF('2. Realization catalog'!$B$2:$B$500,$B22)=0,"",SUMPRODUCT(MAX(('2. Realization catalog'!$B$2:$B$500=$B22)*('2. Realization catalog'!$H$2:$H$500))))
A23: D4 | B23: 4.4 | C23: Agent & Workflow Orchestration Design | D23: Able to design what an agent may pursue, how it plans, and where it must stop. | E23: AI Engineering Owner | F23: New | G23: low | H23: Yes | I23: 6 | J23: 4.4.1 - 4.4.6 | M23: =IF(COUNTIF('2. Realization catalog'!$B$2:$B$500,$B23)=0,"",SUMPRODUCT(MAX(('2. Realization catalog'!$B$2:$B$500=$B23)*('2. Realization catalog'!$H$2:$H$500))))
A24: D4 | B24: 4.5 | C24: Integration & Tool Enablement | D24: Able to give AI systems safe, governed reach into institutional systems. | E24: Integration Architecture Owner | F24: New | G24: medium | H24: Yes | I24: 5 | J24: 4.5.1 - 4.5.5 | M24: =IF(COUNTIF('2. Realization catalog'!$B$2:$B$500,$B24)=0,"",SUMPRODUCT(MAX(('2. Realization catalog'!$B$2:$B$500=$B24)*('2. Realization catalog'!$H$2:$H$500))))
A25: D4 | B25: 4.6 | C25: AI Evaluation & Testing | D25: Able to state, before release, what the system does and does not do reliably. | E25: Quality Engineering Owner | F25: New | G25: medium | I25: 5 | J25: 4.6.1 - 4.6.5 | M25: =IF(COUNTIF('2. Realization catalog'!$B$2:$B$500,$B25)=0,"",SUMPRODUCT(MAX(('2. Realization catalog'!$B$2:$B$500=$B25)*('2. Realization catalog'!$H$2:$H$500))))
A26: D4 | B26: 4.7 | C26: AI Release & Change Management | D26: Able to move AI change into production under control and to reverse it. | E26: DevSecOps Owner | F26: Lens - keep existing node | G26: high | I26: 5 | J26: 4.7.1 - 4.7.5 | M26: =IF(COUNTIF('2. Realization catalog'!$B$2:$B$500,$B26)=0,"",SUMPRODUCT(MAX(('2. Realization catalog'!$B$2:$B$500=$B26)*('2. Realization catalog'!$H$2:$H$500))))
A27: D5 | B27: 5.1 | C27: AI Platform Service Provisioning | D27: Able to offer AI platform services as a governed, supported institutional service. | E27: AI Platform Owner | F27: Specialization | G27: medium | I27: 5 | J27: 5.1.1 - 5.1.5 | M27: =IF(COUNTIF('2. Realization catalog'!$B$2:$B$500,$B27)=0,"",SUMPRODUCT(MAX(('2. Realization catalog'!$B$2:$B$500=$B27)*('2. Realization catalog'!$H$2:$H$500))))
A28: D5 | B28: 5.2 | C28: Model Access & Traffic Management | D28: Able to control which models the institution may call, through one governed path. | E28: AI Platform Owner | F28: New | G28: low | I28: 5 | J28: 5.2.1 - 5.2.5 | M28: =IF(COUNTIF('2. Realization catalog'!$B$2:$B$500,$B28)=0,"",SUMPRODUCT(MAX(('2. Realization catalog'!$B$2:$B$500=$B28)*('2. Realization catalog'!$H$2:$H$500))))
A29: D5 | B29: 5.3 | C29: AI Environment & Workspace Management | D29: Able to give teams isolated places to work without weakening controls. | E29: Cloud Platform Owner | F29: Lens - keep existing node | G29: medium | I29: 4 | J29: 5.3.1 - 5.3.4 | M29: =IF(COUNTIF('2. Realization catalog'!$B$2:$B$500,$B29)=0,"",SUMPRODUCT(MAX(('2. Realization catalog'!$B$2:$B$500=$B29)*('2. Realization catalog'!$H$2:$H$500))))
A30: D5 | B30: 5.4 | C30: AI Compute & Capacity Management | D30: Able to secure and allocate the compute that AI work requires. | E30: Infrastructure Platform Owner | F30: Specialization | G30: medium | I30: 5 | J30: 5.4.1 - 5.4.5 | M30: =IF(COUNTIF('2. Realization catalog'!$B$2:$B$500,$B30)=0,"",SUMPRODUCT(MAX(('2. Realization catalog'!$B$2:$B$500=$B30)*('2. Realization catalog'!$H$2:$H$500))))
A31: D5 | B31: 5.5 | C31: Tool & Connector Catalog Management | D31: Able to control what actions AI systems can reach, as a governed inventory. | E31: Integration Platform Owner | F31: New | G31: low | H31: Yes | I31: 5 | J31: 5.5.1 - 5.5.5 | M31: =IF(COUNTIF('2. Realization catalog'!$B$2:$B$500,$B31)=0,"",SUMPRODUCT(MAX(('2. Realization catalog'!$B$2:$B$500=$B31)*('2. Realization catalog'!$H$2:$H$500))))
A32: D5 | B32: 5.6 | C32: AI Developer Experience & Reuse Assets | D32: Able to make the compliant path the easiest path for delivery teams. | E32: Developer Platform Owner | F32: Specialization | G32: medium | I32: 5 | J32: 5.6.1 - 5.6.5 | M32: =IF(COUNTIF('2. Realization catalog'!$B$2:$B$500,$B32)=0,"",SUMPRODUCT(MAX(('2. Realization catalog'!$B$2:$B$500=$B32)*('2. Realization catalog'!$H$2:$H$500))))
A33: D6 | B33: 6.1 | C33: AI Deployment & Serving Operations | D33: Able to place AI systems into production and keep them serving. | E33: AI Operations Owner | F33: Specialization | G33: medium | H33: Yes | I33: 5 | J33: 6.1.1 - 6.1.5 | M33: =IF(COUNTIF('2. Realization catalog'!$B$2:$B$500,$B33)=0,"",SUMPRODUCT(MAX(('2. Realization catalog'!$B$2:$B$500=$B33)*('2. Realization catalog'!$H$2:$H$500))))
A34: D6 | B34: 6.2 | C34: AI Monitoring & Observability | D34: Able to see what an AI system did, in enough detail to explain it afterwards. | E34: AI SRE Owner | F34: Specialization | G34: medium | H34: Yes | I34: 5 | J34: 6.2.1 - 6.2.5 | M34: =IF(COUNTIF('2. Realization catalog'!$B$2:$B$500,$B34)=0,"",SUMPRODUCT(MAX(('2. Realization catalog'!$B$2:$B$500=$B34)*('2. Realization catalog'!$H$2:$H$500))))
A35: D6 | B35: 6.3 | C35: Continuous Evaluation, Drift & Quality Management | D35: Able to know that a system still performs as it did at release. | E35: AI Product Operations Owner | F35: New | G35: medium | I35: 5 | J35: 6.3.1 - 6.3.5 | M35: =IF(COUNTIF('2. Realization catalog'!$B$2:$B$500,$B35)=0,"",SUMPRODUCT(MAX(('2. Realization catalog'!$B$2:$B$500=$B35)*('2. Realization catalog'!$H$2:$H$500))))
A36: D6 | B36: 6.4 | C36: AI Incident & Problem Management | D36: Able to stop AI harm quickly and account for it afterwards. | E36: Service Operations Owner | F36: Lens - keep existing node | G36: high | H36: Yes | I36: 5 | J36: 6.4.1 - 6.4.5 | M36: =IF(COUNTIF('2. Realization catalog'!$B$2:$B$500,$B36)=0,"",SUMPRODUCT(MAX(('2. Realization catalog'!$B$2:$B$500=$B36)*('2. Realization catalog'!$H$2:$H$500))))
A37: D6 | B37: 6.5 | C37: AI Cost Management | D37: Able to know what AI costs, per unit of value, and to control it. | E37: FinOps Owner | F37: Lens - keep existing node | G37: high | I37: 4 | J37: 6.5.1 - 6.5.4 | M37: =IF(COUNTIF('2. Realization catalog'!$B$2:$B$500,$B37)=0,"",SUMPRODUCT(MAX(('2. Realization catalog'!$B$2:$B$500=$B37)*('2. Realization catalog'!$H$2:$H$500))))
A38: D6 | B38: 6.6 | C38: AI Asset Retirement & Evidence Preservation | D38: Able to retire AI systems deliberately, with their evidence preserved. | E38: Asset Management Owner | F38: Lens - keep existing node | G38: high | I38: 4 | J38: 6.6.1 - 6.6.4 | M38: =IF(COUNTIF('2. Realization catalog'!$B$2:$B$500,$B38)=0,"",SUMPRODUCT(MAX(('2. Realization catalog'!$B$2:$B$500=$B38)*('2. Realization catalog'!$H$2:$H$500))))
A39: D7 | B39: 7.1 | C39: AI Policy, Standards & Management System | D39: Able to operate a functioning management system for AI, not a policy document. | E39: AI Management System Owner | F39: Specialization | G39: medium | I39: 6 | J39: 7.1.1 - 7.1.6 | M39: =IF(COUNTIF('2. Realization catalog'!$B$2:$B$500,$B39)=0,"",SUMPRODUCT(MAX(('2. Realization catalog'!$B$2:$B$500=$B39)*('2. Realization catalog'!$H$2:$H$500))))
A40: D7 | B40: 7.2 | C40: Responsible & Trustworthy AI Practice | D40: Able to make the institution's stated AI principles operative in delivered systems. | E40: Responsible AI Owner | F40: New | G40: medium | H40: Yes | I40: 5 | J40: 7.2.1 - 7.2.5 | M40: =IF(COUNTIF('2. Realization catalog'!$B$2:$B$500,$B40)=0,"",SUMPRODUCT(MAX(('2. Realization catalog'!$B$2:$B$500=$B40)*('2. Realization catalog'!$H$2:$H$500))))
...

Sheet 2. Realization catalog
A1: Realization ID | B1: Capability | C1: Also realizes | D1: Pattern (PAT / ABB) | E1: Technology (SBB) | F1: Supporting building blocks | G1: Operated by | H1: READINESS | I1: Evidence-implied | J1: Consumption model | K1: Status | L1: Preferred | M1: Enterprise assets | N1: Does not provide | O1: Note
A2: REAL-001 | B2: 5.1 | C2: 5.3, 5.4 | D2: Microsoft Foundry Reference Architecture (RA-02) | E2: Microsoft Foundry | F2: IAC-04 Foundry Account; IAC-05 Foundry Project | G2: Consumer - each team deploys and runs its own instance | H2: 4 | I2: =IF(COUNTIFS('3. Enablement evidence'!$A$2:$A$400,$A2,'3. Enablement evidence'!$D$2:$D$400,"Generic")=0,"",IF(COUNTIFS('3. Enablement evidence'!$A$2:$A$400,$A2,'3. Enablement evidence'!$D$2:$D$400,"Generic",'3. Enablement evidence'!$G$2:$G$400,"Yes")+COUNTIFS('3. Enablement evidence'!$A$2:$A$400,$A2,'3. Enablement evidence'!$D$2:$D$400,"Generic",'3. Enablement evidence'!$G$2:$G$400,"No")+COUNTIFS('3. Enablement evidence'!$A$2:$A$400,$A2,'3. Enablement evidence'!$D$2:$D$400,"Generic",'3. Enablement evidence'!$G$2:$G$400,"Partial")=0,"no evidence",IF(COUNTIFS('3. Enablement evidence'!$A$2:$A$400,$A2,'3. Enablement evidence'!$D$2:$D$400,"Generic",'3. Enablement evidence'!$G$2:$G$400,"Yes")+COUNTIFS('3. Enablement evidence'!$A$2:$A$400,$A2,'3. Enablement evidence'!$D$2:$D$400,"Generic",'3. Enablement evidence'!$G$2:$G$400,"No")+COUNTIFS('3. Enablement evidence'!$A$2:$A$400,$A2,'3. Enablement evidence'!$D$2:$D$400,"Generic",'3. Enablement evidence'!$G$2:$G$400,"Partial")<COUNTIFS('3. Enablement evidence'!$A$2:$A$400,$A2,'3. Enablement evidence'!$D$2:$D$400,"Generic"),"incomplete "&COUNTIFS('3. Enablement evidence'!$A$2:$A$400,$A2,'3. Enablement evidence'!$D$2:$D$400,"Generic",'3. Enablement evidence'!$G$2:$G$400,"Yes")&"/"&COUNTIFS('3. Enablement evidence'!$A$2:$A$400,$A2,'3. Enablement evidence'!$D$2:$D$400,"Generic"),IF(COUNTIFS('3. Enablement evidence'!$A$2:$A$400,$A2,'3. Enablement evidence'!$D$2:$D$400,"Generic",'3. Enablement evidence'!$G$2:$G$400,"Yes")>=8,4,IF(AND(COUNTIFS('3. Enablement evidence'!$A$2:$A$400,$A2,'3. Enablement evidence'!$C$2:$C$400,"Published standard",'3. Enablement evidence'!$G$2:$G$400,"Yes")=1,COUNTIFS('3. Enablement evidence'!$A$2:$A$400,$A2,'3. Enablement evidence'!$C$2:$C$400,"Architecture pattern document",'3. Enablement evidence'!$G$2:$G$400,"Yes")+COUNTIFS('3. Enablement evidence'!$A$2:$A$400,$A2,'3. Enablement evidence'!$C$2:$C$400,"Reference architecture",'3. Enablement evidence'!$G$2:$G$400,"Yes")>=1),3,IF(COUNTIFS('3. Enablement evidence'!$A$2:$A$400,$A2,'3. Enablement evidence'!$D$2:$D$400,"Generic",'3. Enablement evidence'!$G$2:$G$400,"Yes")>=1,2,1)))))) | J2: Building blocks | K2: Approved | L2: Y | M2: STD-03, RA-02, IAC-04, IAC-05 | O2: Standard published, reference architecture published, both Terraform modules published in JFrog. This is the strongest realization in the estate.
A3: REAL-002 | B3: 5.1 | C3: 5.6, 4.4 | D3: Foundry Agents Reference Architecture (RA-05, PRE-RELEASE) | E3: Microsoft Foundry | F3: IAC-04; IAC-05; IAC-02 Container Apps; STD-06 AI Agent Decision Tree | G3: Consumer - each team deploys and runs its own instance | H3: 3 | I3: =IF(COUNTIFS('3. Enablement evidence'!$A$2:$A$400,$A3,'3. Enablement evidence'!$D$2:$D$400,"Generic")=0,"",IF(COUNTIFS('3. Enablement evidence'!$A$2:$A$400,$A3,'3. Enablement evidence'!$D$2:$D$400,"Generic",'3. Enablement evidence'!$G$2:$G$400,"Yes")+COUNTIFS('3. Enablement evidence'!$A$2:$A$400,$A3,'3. Enablement evidence'!$D$2:$D$400,"Generic",'3. Enablement evidence'!$G$2:$G$400,"No")+COUNTIFS('3. Enablement evidence'!$A$2:$A$400,$A3,'3. Enablement evidence'!$D$2:$D$400,"Generic",'3. Enablement evidence'!$G$2:$G$400,"Partial")=0,"no evidence",IF(COUNTIFS('3. Enablement evidence'!$A$2:$A$400,$A3,'3. Enablement evidence'!$D$2:$D$400,"Generic",'3. Enablement evidence'!$G$2:$G$400,"Yes")+COUNTIFS('3. Enablement evidence'!$A$2:$A$400,$A3,'3. Enablement evidence'!$D$2:$D$400,"Generic",'3. Enablement evidence'!$G$2:$G$400,"No")+COUNTIFS('3. Enablement evidence'!$A$2:$A$400,$A3,'3. Enablement evidence'!$D$2:$D$400,"Generic",'3. Enablement evidence'!$G$2:$G$400,"Partial")<COUNTIFS('3. Enablement evidence'!$A$2:$A$400,$A3,'3. Enablement evidence'!$D$2:$D$400,"Generic"),"incomplete "&COUNTIFS('3. Enablement evidence'!$A$2:$A$400,$A3,'3. Enablement evidence'!$D$2:$D$400,"Generic",'3. Enablement evidence'!$G$2:$G$400,"Yes")&"/"&COUNTIFS('3. Enablement evidence'!$A$2:$A$400,$A3,'3. Enablement evidence'!$D$2:$D$400,"Generic"),IF(COUNTIFS('3. Enablement evidence'!$A$2:$A$400,$A3,'3. Enablement evidence'!$D$2:$D$400,"Generic",'3. Enablement evidence'!$G$2:$G$400,"Yes")>=8,4,IF(AND(COUNTIFS('3. Enablement evidence'!$A$2:$A$400,$A3,'3. Enablement evidence'!$C$2:$C$400,"Published standard",'3. Enablement evidence'!$G$2:$G$400,"Yes")=1,COUNTIFS('3. Enablement evidence'!$A$2:$A$400,$A3,'3. Enablement evidence'!$C$2:$C$400,"Architecture pattern document",'3. Enablement evidence'!$G$2:$G$400,"Yes")+COUNTIFS('3. Enablement evidence'!$A$2:$A$400,$A3,'3. Enablement evidence'!$C$2:$C$400,"Reference architecture",'3. Enablement evidence'!$G$2:$G$400,"Yes")>=1),3,IF(COUNTIFS('3. Enablement evidence'!$A$2:$A$400,$A3,'3. Enablement evidence'!$D$2:$D$400,"Generic",'3. Enablement evidence'!$G$2:$G$400,"Yes")>=1,2,1)))))) | J3: Building blocks | K3: Approved | L3: Y | M3: STD-03, STD-07, RA-02, RA-05, IAC-04, IAC-05, IAC-02, STD-06 | N3: The agent itself: business rules, grounding data, evaluation criteria, human oversight design. Those remain with the delivery team. | O3: READINESS 3, NOT 4 - and only because the documentation trails the engineering. The Terraform modules are published and in use; the Foundry Agents Standard (STD-07) and its Reference Architecture (RA-05) are both PRE-RELEASE. Releasing those two documents is the whole distance to 4. Confirm this reading.
A4: REAL-003 | B4: 4.5 | C4: 5.5 | D4: Custom MCP Server Reference Architecture (RA-01) | E4: C# / .NET on Azure Container Apps | F4: TPL-01 template v1 (in use); TPL-02 template v2 (built, not distributed); IAC-02 published; IAC-01 and IAC-03 in review | G4: Consumer - each team deploys and runs its own server | H4: 4 | I4: =IF(COUNTIFS('3. Enablement evidence'!$A$2:$A$400,$A4,'3. Enablement evidence'!$D$2:$D$400,"Generic")=0,"",IF(COUNTIFS('3. Enablement evidence'!$A$2:$A$400,$A4,'3. Enablement evidence'!$D$2:$D$400,"Generic",'3. Enablement evidence'!$G$2:$G$400,"Yes")+COUNTIFS('3. Enablement evidence'!$A$2:$A$400,$A4,'3. Enablement evidence'!$D$2:$D$400,"Generic",'3. Enablement evidence'!$G$2:$G$400,"No")+COUNTIFS('3. Enablement evidence'!$A$2:$A$400,$A4,'3. Enablement evidence'!$D$2:$D$400,"Generic",'3. Enablement evidence'!$G$2:$G$400,"Partial")=0,"no evidence",IF(COUNTIFS('3. Enablement evidence'!$A$2:$A$400,$A4,'3. Enablement evidence'!$D$2:$D$400,"Generic",'3. Enablement evidence'!$G$2:$G$400,"Yes")+COUNTIFS('3. Enablement evidence'!$A$2:$A$400,$A4,'3. Enablement evidence'!$D$2:$D$400,"Generic",'3. Enablement evidence'!$G$2:$G$400,"No")+COUNTIFS('3. Enablement evidence'!$A$2:$A$400,$A4,'3. Enablement evidence'!$D$2:$D$400,"Generic",'3. Enablement evidence'!$G$2:$G$400,"Partial")<COUNTIFS('3. Enablement evidence'!$A$2:$A$400,$A4,'3. Enablement evidence'!$D$2:$D$400,"Generic"),"incomplete "&COUNTIFS('3. Enablement evidence'!$A$2:$A$400,$A4,'3. Enablement evidence'!$D$2:$D$400,"Generic",'3. Enablement evidence'!$G$2:$G$400,"Yes")&"/"&COUNTIFS('3. Enablement evidence'!$A$2:$A$400,$A4,'3. Enablement evidence'!$D$2:$D$400,"Generic"),IF(COUNTIFS('3. Enablement evidence'!$A$2:$A$400,$A4,'3. Enablement evidence'!$D$2:$D$400,"Generic",'3. Enablement evidence'!$G$2:$G$400,"Yes")>=8,4,IF(AND(COUNTIFS('3. Enablement evidence'!$A$2:$A$400,$A4,'3. Enablement evidence'!$C$2:$C$400,"Published standard",'3. Enablement evidence'!$G$2:$G$400,"Yes")=1,COUNTIFS('3. Enablement evidence'!$A$2:$A$400,$A4,'3. Enablement evidence'!$C$2:$C$400,"Architecture pattern document",'3. Enablement evidence'!$G$2:$G$400,"Yes")+COUNTIFS('3. Enablement evidence'!$A$2:$A$400,$A4,'3. Enablement evidence'!$C$2:$C$400,"Reference architecture",'3. Enablement evidence'!$G$2:$G$400,"Yes")>=1),3,IF(COUNTIFS('3. Enablement evidence'!$A$2:$A$400,$A4,'3. Enablement evidence'!$D$2:$D$400,"Generic",'3. Enablement evidence'!$G$2:$G$400,"Yes")>=1,2,1)))))) | J4: Reference implementation | K4: Approved | L4: Y | M4: STD-02, RA-01, TPL-01, TPL-02, IAC-02, IAC-01, IAC-03 | O4: Standard, reference architecture and a working template that built every custom MCP server on the AI MVP project. TEMPLATE v1 IMPLEMENTS THE SUPERSEDED MCP SPECIFICATION - the July 2026 revision deprecated Roots, Sampling, Logging, RFC 7591 dynamic client registration and the legacy HTTP+SSE transport on defined timelines. Every server built from v1 needs a migration plan inside that window, and v2 is built but not yet distributed. That is a dated roadmap item, not a maturity opinion.
A5: REAL-004 | B5: 3.6 | D5: Azure AI Search Reference Architecture (RA-03) - hybrid / semantic retrieval | E5: Azure AI Search | F5: IAC-06 AI Search module (published) | G5: Consumer | H5: 4 | I5: =IF(COUNTIFS('3. Enablement evidence'!$A$2:$A$400,$A5,'3. Enablement evidence'!$D$2:$D$400,"Generic")=0,"",IF(COUNTIFS('3. Enablement evidence'!$A$2:$A$400,$A5,'3. Enablement evidence'!$D$2:$D$400,"Generic",'3. Enablement evidence'!$G$2:$G$400,"Yes")+COUNTIFS('3. Enablement evidence'!$A$2:$A$400,$A5,'3. Enablement evidence'!$D$2:$D$400,"Generic",'3. Enablement evidence'!$G$2:$G$400,"No")+COUNTIFS('3. Enablement evidence'!$A$2:$A$400,$A5,'3. Enablement evidence'!$D$2:$D$400,"Generic",'3. Enablement evidence'!$G$2:$G$400,"Partial")=0,"no evidence",IF(COUNTIFS('3. Enablement evidence'!$A$2:$A$400,$A5,'3. Enablement evidence'!$D$2:$D$400,"Generic",'3. Enablement evidence'!$G$2:$G$400,"Yes")+COUNTIFS('3. Enablement evidence'!$A$2:$A$400,$A5,'3. Enablement evidence'!$D$2:$D$400,"Generic",'3. Enablement evidence'!$G$2:$G$400,"No")+COUNTIFS('3. Enablement evidence'!$A$2:$A$400,$A5,'3. Enablement evidence'!$D$2:$D$400,"Generic",'3. Enablement evidence'!$G$2:$G$400,"Partial")<COUNTIFS('3. Enablement evidence'!$A$2:$A$400,$A5,'3. Enablement evidence'!$D$2:$D$400,"Generic"),"incomplete "&COUNTIFS('3. Enablement evidence'!$A$2:$A$400,$A5,'3. Enablement evidence'!$D$2:$D$400,"Generic",'3. Enablement evidence'!$G$2:$G$400,"Yes")&"/"&COUNTIFS('3. Enablement evidence'!$A$2:$A$400,$A5,'3. Enablement evidence'!$D$2:$D$400,"Generic"),IF(COUNTIFS('3. Enablement evidence'!$A$2:$A$400,$A5,'3. Enablement evidence'!$D$2:$D$400,"Generic",'3. Enablement evidence'!$G$2:$G$400,"Yes")>=8,4,IF(AND(COUNTIFS('3. Enablement evidence'!$A$2:$A$400,$A5,'3. Enablement evidence'!$C$2:$C$400,"Published standard",'3. Enablement evidence'!$G$2:$G$400,"Yes")=1,COUNTIFS('3. Enablement evidence'!$A$2:$A$400,$A5,'3. Enablement evidence'!$C$2:$C$400,"Architecture pattern document",'3. Enablement evidence'!$G$2:$G$400,"Yes")+COUNTIFS('3. Enablement evidence'!$A$2:$A$400,$A5,'3. Enablement evidence'!$C$2:$C$400,"Reference architecture",'3. Enablement evidence'!$G$2:$G$400,"Yes")>=1),3,IF(COUNTIFS('3. Enablement evidence'!$A$2:$A$400,$A5,'3. Enablement evidence'!$D$2:$D$400,"Generic",'3. Enablement evidence'!$G$2:$G$400,"Yes")>=1,2,1)))))) | J5: Building blocks | K5: Approved | L5: Y | M5: STD-04, RA-03, IAC-06 | O5: Standard, reference architecture and a published Terraform module. Supply is well packaged - which is exactly why the maturity of capability 3.6 must be argued separately. See REAL-005.
A6: REAL-005 | B6: 3.6 | D6: S3.10 Access-Trimmed Retrieval | I6: =IF(COUNTIFS('3. Enablement evidence'!$A$2:$A$400,$A6,'3. Enablement evidence'!$D$2:$D$400,"Generic")=0,"",IF(COUNTIFS('3. Enablement evidence'!$A$2:$A$400,$A6,'3. Enablement evidence'!$D$2:$D$400,"Generic",'3. Enablement evidence'!$G$2:$G$400,"Yes")+COUNTIFS('3. Enablement evidence'!$A$2:$A$400,$A6,'3. Enablement evidence'!$D$2:$D$400,"Generic",'3. Enablement evidence'!$G$2:$G$400,"No")+COUNTIFS('3. Enablement evidence'!$A$2:$A$400,$A6,'3. Enablement evidence'!$D$2:$D$400,"Generic",'3. Enablement evidence'!$G$2:$G$400,"Partial")=0,"no evidence",IF(COUNTIFS('3. Enablement evidence'!$A$2:$A$400,$A6,'3. Enablement evidence'!$D$2:$D$400,"Generic",'3. Enablement evidence'!$G$2:$G$400,"Yes")+COUNTIFS('3. Enablement evidence'!$A$2:$A$400,$A6,'3. Enablement evidence'!$D$2:$D$400,"Generic",'3. Enablement evidence'!$G$2:$G$400,"No")+COUNTIFS('3. Enablement evidence'!$A$2:$A$400,$A6,'3. Enablement evidence'!$D$2:$D$400,"Generic",'3. Enablement evidence'!$G$2:$G$400,"Partial")<COUNTIFS('3. Enablement evidence'!$A$2:$A$400,$A6,'3. Enablement evidence'!$D$2:$D$400,"Generic"),"incomplete "&COUNTIFS('3. Enablement evidence'!$A$2:$A$400,$A6,'3. Enablement evidence'!$D$2:$D$400,"Generic",'3. Enablement evidence'!$G$2:$G$400,"Yes")&"/"&COUNTIFS('3. Enablement evidence'!$A$2:$A$400,$A6,'3. Enablement evidence'!$D$2:$D$400,"Generic"),IF(COUNTIFS('3. Enablement evidence'!$A$2:$A$400,$A6,'3. Enablement evidence'!$D$2:$D$400,"Generic",'3. Enablement evidence'!$G$2:$G$400,"Yes")>=8,4,IF(AND(COUNTIFS('3. Enablement evidence'!$A$2:$A$400,$A6,'3. Enablement evidence'!$C$2:$C$400,"Published standard",'3. Enablement evidence'!$G$2:$G$400,"Yes")=1,COUNTIFS('3. Enablement evidence'!$A$2:$A$400,$A6,'3. Enablement evidence'!$C$2:$C$400,"Architecture pattern document",'3. Enablement evidence'!$G$2:$G$400,"Yes")+COUNTIFS('3. Enablement evidence'!$A$2:$A$400,$A6,'3. Enablement evidence'!$C$2:$C$400,"Reference architecture",'3. Enablement evidence'!$G$2:$G$400,"Yes")>=1),3,IF(COUNTIFS('3. Enablement evidence'!$A$2:$A$400,$A6,'3. Enablement evidence'!$D$2:$D$400,"Generic",'3. Enablement evidence'!$G$2:$G$400,"Yes")>=1,2,1)))))) | M6: STD-04, RA-03 | O6: CONFIRM THIS ROW - it decides the headline finding for D3. Does the Azure AI Search Standard (STD-04) mandate that source ACL metadata is extracted, indexed and applied as a pre-ranking filter? If it does, readiness follows REAL-004. If it does not, this sits at 0 and it is the reason capability 3.6 can carry readiness 4 and a much lower maturity. Filtering a ranked list after the fact both leaks and distorts relevance.
A7: REAL-006 | B7: 3.5 | D7: Azure Document Intelligence Reference Architecture (RA-04) | E7: Azure AI Document Intelligence | G7: Consumer | H7: 3 | I7: =IF(COUNTIFS('3. Enablement evidence'!$A$2:$A$400,$A7,'3. Enablement evidence'!$D$2:$D$400,"Generic")=0,"",IF(COUNTIFS('3. Enablement evidence'!$A$2:$A$400,$A7,'3. Enablement evidence'!$D$2:$D$400,"Generic",'3. Enablement evidence'!$G$2:$G$400,"Yes")+COUNTIFS('3. Enablement evidence'!$A$2:$A$400,$A7,'3. Enablement evidence'!$D$2:$D$400,"Generic",'3. Enablement evidence'!$G$2:$G$400,"No")+COUNTIFS('3. Enablement evidence'!$A$2:$A$400,$A7,'3. Enablement evidence'!$D$2:$D$400,"Generic",'3. Enablement evidence'!$G$2:$G$400,"Partial")=0,"no evidence",IF(COUNTIFS('3. Enablement evidence'!$A$2:$A$400,$A7,'3. Enablement evidence'!$D$2:$D$400,"Generic",'3. Enablement evidence'!$G$2:$G$400,"Yes")+COUNTIFS('3. Enablement evidence'!$A$2:$A$400,$A7,'3. Enablement evidence'!$D$2:$D$400,"Generic",'3. Enablement evidence'!$G$2:$G$400,"No")+COUNTIFS('3. Enablement evidence'!$A$2:$A$400,$A7,'3. Enablement evidence'!$D$2:$D$400,"Generic",'3. Enablement evidence'!$G$2:$G$400,"Partial")<COUNTIFS('3. Enablement evidence'!$A$2:$A$400,$A7,'3. Enablement evidence'!$D$2:$D$400,"Generic"),"incomplete "&COUNTIFS('3. Enablement evidence'!$A$2:$A$400,$A7,'3. Enablement evidence'!$D$2:$D$400,"Generic",'3. Enablement evidence'!$G$2:$G$400,"Yes")&"/"&COUNTIFS('3. Enablement evidence'!$A$2:$A$400,$A7,'3. Enablement evidence'!$D$2:$D$400,"Generic"),IF(COUNTIFS('3. Enablement evidence'!$A$2:$A$400,$A7,'3. Enablement evidence'!$D$2:$D$400,"Generic",'3. Enablement evidence'!$G$2:$G$400,"Yes")>=8,4,IF(AND(COUNTIFS('3. Enablement evidence'!$A$2:$A$400,$A7,'3. Enablement evidence'!$C$2:$C$400,"Published standard",'3. Enablement evidence'!$G$2:$G$400,"Yes")=1,COUNTIFS('3. Enablement evidence'!$A$2:$A$400,$A7,'3. Enablement evidence'!$C$2:$C$400,"Architecture pattern document",'3. Enablement evidence'!$G$2:$G$400,"Yes")+COUNTIFS('3. Enablement evidence'!$A$2:$A$400,$A7,'3. Enablement evidence'!$C$2:$C$400,"Reference architecture",'3. Enablement evidence'!$G$2:$G$400,"Yes")>=1),3,IF(COUNTIFS('3. Enablement evidence'!$A$2:$A$400,$A7,'3. Enablement evidence'!$D$2:$D$400,"Generic",'3. Enablement evidence'!$G$2:$G$400,"Yes")>=1,2,1)))))) | J7: Guidance | K7: Approved | L7: Y | M7: STD-05, RA-04 | O7: Standard and reference architecture published; no Terraform module in the inventory. Publishing one is the step to 4.
A8: REAL-007 | B8: 4.1 | C8: 5.2 | D8: Tech Stack - AI standard (STD-01) | G8: - | H8: 3 | I8: =IF(COUNTIFS('3. Enablement evidence'!$A$2:$A$400,$A8,'3. Enablement evidence'!$D$2:$D$400,"Generic")=0,"",IF(COUNTIFS('3. Enablement evidence'!$A$2:$A$400,$A8,'3. Enablement evidence'!$D$2:$D$400,"Generic",'3. Enablement evidence'!$G$2:$G$400,"Yes")+COUNTIFS('3. Enablement evidence'!$A$2:$A$400,$A8,'3. Enablement evidence'!$D$2:$D$400,"Generic",'3. Enablement evidence'!$G$2:$G$400,"No")+COUNTIFS('3. Enablement evidence'!$A$2:$A$400,$A8,'3. Enablement evidence'!$D$2:$D$400,"Generic",'3. Enablement evidence'!$G$2:$G$400,"Partial")=0,"no evidence",IF(COUNTIFS('3. Enablement evidence'!$A$2:$A$400,$A8,'3. Enablement evidence'!$D$2:$D$400,"Generic",'3. Enablement evidence'!$G$2:$G$400,"Yes")+COUNTIFS('3. Enablement evidence'!$A$2:$A$400,$A8,'3. Enablement evidence'!$D$2:$D$400,"Generic",'3. Enablement evidence'!$G$2:$G$400,"No")+COUNTIFS('3. Enablement evidence'!$A$2:$A$400,$A8,'3. Enablement evidence'!$D$2:$D$400,"Generic",'3. Enablement evidence'!$G$2:$G$400,"Partial")<COUNTIFS('3. Enablement evidence'!$A$2:$A$400,$A8,'3. Enablement evidence'!$D$2:$D$400,"Generic"),"incomplete "&COUNTIFS('3. Enablement evidence'!$A$2:$A$400,$A8,'3. Enablement evidence'!$D$2:$D$400,"Generic",'3. Enablement evidence'!$G$2:$G$400,"Yes")&"/"&COUNTIFS('3. Enablement evidence'!$A$2:$A$400,$A8,'3. Enablement evidence'!$D$2:$D$400,"Generic"),IF(COUNTIFS('3. Enablement evidence'!$A$2:$A$400,$A8,'3. Enablement evidence'!$D$2:$D$400,"Generic",'3. Enablement evidence'!$G$2:$G$400,"Yes")>=8,4,IF(AND(COUNTIFS('3. Enablement evidence'!$A$2:$A$400,$A8,'3. Enablement evidence'!$C$2:$C$400,"Published standard",'3. Enablement evidence'!$G$2:$G$400,"Yes")=1,COUNTIFS('3. Enablement evidence'!$A$2:$A$400,$A8,'3. Enablement evidence'!$C$2:$C$400,"Architecture pattern document",'3. Enablement evidence'!$G$2:$G$400,"Yes")+COUNTIFS('3. Enablement evidence'!$A$2:$A$400,$A8,'3. Enablement evidence'!$C$2:$C$400,"Reference architecture",'3. Enablement evidence'!$G$2:$G$400,"Yes")>=1),3,IF(COUNTIFS('3. Enablement evidence'!$A$2:$A$400,$A8,'3. Enablement evidence'!$D$2:$D$400,"Generic",'3. Enablement evidence'!$G$2:$G$400,"Yes")>=1,2,1)))))) | J8: Guidance | K8: Approved | L8: Y | M8: STD-01 | O8: The approved AI technology stack. This is the asset that answers 'what is already approved for general use' at the technology level - it is evidence toward capability maturity, not a substitute for it.
A9: REAL-008 | B9: 2.5 | C9: 2.2 | D9: AI Agent Decision Tree (STD-06) | G9: - | H9: 3 | I9: =IF(COUNTIFS('3. Enablement evidence'!$A$2:$A$400,$A9,'3. Enablement evidence'!$D$2:$D$400,"Generic")=0,"",IF(COUNTIFS('3. Enablement evidence'!$A$2:$A$400,$A9,'3. Enablement evidence'!$D$2:$D$400,"Generic",'3. Enablement evidence'!$G$2:$G$400,"Yes")+COUNTIFS('3. Enablement evidence'!$A$2:$A$400,$A9,'3. Enablement evidence'!$D$2:$D$400,"Generic",'3. Enablement evidence'!$G$2:$G$400,"No")+COUNTIFS('3. Enablement evidence'!$A$2:$A$400,$A9,'3. Enablement evidence'!$D$2:$D$400,"Generic",'3. Enablement evidence'!$G$2:$G$400,"Partial")=0,"no evidence",IF(COUNTIFS('3. Enablement evidence'!$A$2:$A$400,$A9,'3. Enablement evidence'!$D$2:$D$400,"Generic",'3. Enablement evidence'!$G$2:$G$400,"Yes")+COUNTIFS('3. Enablement evidence'!$A$2:$A$400,$A9,'3. Enablement evidence'!$D$2:$D$400,"Generic",'3. Enablement evidence'!$G$2:$G$400,"No")+COUNTIFS('3. Enablement evidence'!$A$2:$A$400,$A9,'3. Enablement evidence'!$D$2:$D$400,"Generic",'3. Enablement evidence'!$G$2:$G$400,"Partial")<COUNTIFS('3. Enablement evidence'!$A$2:$A$400,$A9,'3. Enablement evidence'!$D$2:$D$400,"Generic"),"incomplete "&COUNTIFS('3. Enablement evidence'!$A$2:$A$400,$A9,'3. Enablement evidence'!$D$2:$D$400,"Generic",'3. Enablement evidence'!$G$2:$G$400,"Yes")&"/"&COUNTIFS('3. Enablement evidence'!$A$2:$A$400,$A9,'3. Enablement evidence'!$D$2:$D$400,"Generic"),IF(COUNTIFS('3. Enablement evidence'!$A$2:$A$400,$A9,'3. Enablement evidence'!$D$2:$D$400,"Generic",'3. Enablement evidence'!$G$2:$G$400,"Yes")>=8,4,IF(AND(COUNTIFS('3. Enablement evidence'!$A$2:$A$400,$A9,'3. Enablement evidence'!$C$2:$C$400,"Published standard",'3. Enablement evidence'!$G$2:$G$400,"Yes")=1,COUNTIFS('3. Enablement evidence'!$A$2:$A$400,$A9,'3. Enablement evidence'!$C$2:$C$400,"Architecture pattern document",'3. Enablement evidence'!$G$2:$G$400,"Yes")+COUNTIFS('3. Enablement evidence'!$A$2:$A$400,$A9,'3. Enablement evidence'!$C$2:$C$400,"Reference architecture",'3. Enablement evidence'!$G$2:$G$400,"Yes")>=1),3,IF(COUNTIFS('3. Enablement evidence'!$A$2:$A$400,$A9,'3. Enablement evidence'!$D$2:$D$400,"Generic",'3. Enablement evidence'!$G$2:$G$400,"Yes")>=1,2,1)))))) | J9: Guidance | K9: Approved | L9: Y | M9: STD-06 | O9: A published decision aid for whether and what kind of agent is appropriate. This is the only realization currently touching domain D2, and it maps to the autonomy and interaction-pattern determination.
A10: REAL-200 | B10: 3.5 | D10: S1.1 Optical Character Recognition | I10: =IF(COUNTIFS('3. Enablement evidence'!$A$2:$A$400,$A10,'3. Enablement evidence'!$D$2:$D$400,"Generic")=0,"",IF(COUNTIFS('3. Enablement evidence'!$A$2:$A$400,$A10,'3. Enablement evidence'!$D$2:$D$400,"Generic",'3. Enablement evidence'!$G$2:$G$400,"Yes")+COUNTIFS('3. Enablement evidence'!$A$2:$A$400,$A10,'3. Enablement evidence'!$D$2:$D$400,"Generic",'3. Enablement evidence'!$G$2:$G$400,"No")+COUNTIFS('3. Enablement evidence'!$A$2:$A$400,$A10,'3. Enablement evidence'!$D$2:$D$400,"Generic",'3. Enablement evidence'!$G$2:$G$400,"Partial")=0,"no evidence",IF(COUNTIFS('3. Enablement evidence'!$A$2:$A$400,$A10,'3. Enablement evidence'!$D$2:$D$400,"Generic",'3. Enablement evidence'!$G$2:$G$400,"Yes")+COUNTIFS('3. Enablement evidence'!$A$2:$A$400,$A10,'3. Enablement evidence'!$D$2:$D$400,"Generic",'3. Enablement evidence'!$G$2:$G$400,"No")+COUNTIFS('3. Enablement evidence'!$A$2:$A$400,$A10,'3. Enablement evidence'!$D$2:$D$400,"Generic",'3. Enablement evidence'!$G$2:$G$400,"Partial")<COUNTIFS('3. Enablement evidence'!$A$2:$A$400,$A10,'3. Enablement evidence'!$D$2:$D$400,"Generic"),"incomplete "&COUNTIFS('3. Enablement evidence'!$A$2:$A$400,$A10,'3. Enablement evidence'!$D$2:$D$400,"Generic",'3. Enablement evidence'!$G$2:$G$400,"Yes")&"/"&COUNTIFS('3. Enablement evidence'!$A$2:$A$400,$A10,'3. Enablement evidence'!$D$2:$D$400,"Generic"),IF(COUNTIFS('3. Enablement evidence'!$A$2:$A$400,$A10,'3. Enablement evidence'!$D$2:$D$400,"Generic",'3. Enablement evidence'!$G$2:$G$400,"Yes")>=8,4,IF(AND(COUNTIFS('3. Enablement evidence'!$A$2:$A$400,$A10,'3. Enablement evidence'!$C$2:$C$400,"Published standard",'3. Enablement evidence'!$G$2:$G$400,"Yes")=1,COUNTIFS('3. Enablement evidence'!$A$2:$A$400,$A10,'3. Enablement evidence'!$C$2:$C$400,"Architecture pattern document",'3. Enablement evidence'!$G$2:$G$400,"Yes")+COUNTIFS('3. Enablement evidence'!$A$2:$A$400,$A10,'3. Enablement evidence'!$C$2:$C$400,"Reference architecture",'3. Enablement evidence'!$G$2:$G$400,"Yes")>=1),3,IF(COUNTIFS('3. Enablement evidence'!$A$2:$A$400,$A10,'3. Enablement evidence'!$D$2:$D$400,"Generic",'3. Enablement evidence'!$G$2:$G$400,"Yes")>=1,2,1)))))) | K10: Candidate
A11: REAL-201 | B11: 3.5 | D11: S1.2 Document Layout & Structure Analysis | I11: =IF(COUNTIFS('3. Enablement evidence'!$A$2:$A$400,$A11,'3. Enablement evidence'!$D$2:$D$400,"Generic")=0,"",IF(COUNTIFS('3. Enablement evidence'!$A$2:$A$400,$A11,'3. Enablement evidence'!$D$2:$D$400,"Generic",'3. Enablement evidence'!$G$2:$G$400,"Yes")+COUNTIFS('3. Enablement evidence'!$A$2:$A$400,$A11,'3. Enablement evidence'!$D$2:$D$400,"Generic",'3. Enablement evidence'!$G$2:$G$400,"No")+COUNTIFS('3. Enablement evidence'!$A$2:$A$400,$A11,'3. Enablement evidence'!$D$2:$D$400,"Generic",'3. Enablement evidence'!$G$2:$G$400,"Partial")=0,"no evidence",IF(COUNTIFS('3. Enablement evidence'!$A$2:$A$400,$A11,'3. Enablement evidence'!$D$2:$D$400,"Generic",'3. Enablement evidence'!$G$2:$G$400,"Yes")+COUNTIFS('3. Enablement evidence'!$A$2:$A$400,$A11,'3. Enablement evidence'!$D$2:$D$400,"Generic",'3. Enablement evidence'!$G$2:$G$400,"No")+COUNTIFS('3. Enablement evidence'!$A$2:$A$400,$A11,'3. Enablement evidence'!$D$2:$D$400,"Generic",'3. Enablement evidence'!$G$2:$G$400,"Partial")<COUNTIFS('3. Enablement evidence'!$A$2:$A$400,$A11,'3. Enablement evidence'!$D$2:$D$400,"Generic"),"incomplete "&COUNTIFS('3. Enablement evidence'!$A$2:$A$400,$A11,'3. Enablement evidence'!$D$2:$D$400,"Generic",'3. Enablement evidence'!$G$2:$G$400,"Yes")&"/"&COUNTIFS('3. Enablement evidence'!$A$2:$A$400,$A11,'3. Enablement evidence'!$D$2:$D$400,"Generic"),IF(COUNTIFS('3. Enablement evidence'!$A$2:$A$400,$A11,'3. Enablement evidence'!$D$2:$D$400,"Generic",'3. Enablement evidence'!$G$2:$G$400,"Yes")>=8,4,IF(AND(COUNTIFS('3. Enablement evidence'!$A$2:$A$400,$A11,'3. Enablement evidence'!$C$2:$C$400,"Published standard",'3. Enablement evidence'!$G$2:$G$400,"Yes")=1,COUNTIFS('3. Enablement evidence'!$A$2:$A$400,$A11,'3. Enablement evidence'!$C$2:$C$400,"Architecture pattern document",'3. Enablement evidence'!$G$2:$G$400,"Yes")+COUNTIFS('3. Enablement evidence'!$A$2:$A$400,$A11,'3. Enablement evidence'!$C$2:$C$400,"Reference architecture",'3. Enablement evidence'!$G$2:$G$400,"Yes")>=1),3,IF(COUNTIFS('3. Enablement evidence'!$A$2:$A$400,$A11,'3. Enablement evidence'!$D$2:$D$400,"Generic",'3. Enablement evidence'!$G$2:$G$400,"Yes")>=1,2,1)))))) | K11: Candidate
A12: REAL-202 | B12: 3.5 | D12: S1.3 Form & Key-Value Extraction | I12: =IF(COUNTIFS('3. Enablement evidence'!$A$2:$A$400,$A12,'3. Enablement evidence'!$D$2:$D$400,"Generic")=0,"",IF(COUNTIFS('3. Enablement evidence'!$A$2:$A$400,$A12,'3. Enablement evidence'!$D$2:$D$400,"Generic",'3. Enablement evidence'!$G$2:$G$400,"Yes")+COUNTIFS('3. Enablement evidence'!$A$2:$A$400,$A12,'3. Enablement evidence'!$D$2:$D$400,"Generic",'3. Enablement evidence'!$G$2:$G$400,"No")+COUNTIFS('3. Enablement evidence'!$A$2:$A$400,$A12,'3. Enablement evidence'!$D$2:$D$400,"Generic",'3. Enablement evidence'!$G$2:$G$400,"Partial")=0,"no evidence",IF(COUNTIFS('3. Enablement evidence'!$A$2:$A$400,$A12,'3. Enablement evidence'!$D$2:$D$400,"Generic",'3. Enablement evidence'!$G$2:$G$400,"Yes")+COUNTIFS('3. Enablement evidence'!$A$2:$A$400,$A12,'3. Enablement evidence'!$D$2:$D$400,"Generic",'3. Enablement evidence'!$G$2:$G$400,"No")+COUNTIFS('3. Enablement evidence'!$A$2:$A$400,$A12,'3. Enablement evidence'!$D$2:$D$400,"Generic",'3. Enablement evidence'!$G$2:$G$400,"Partial")<COUNTIFS('3. Enablement evidence'!$A$2:$A$400,$A12,'3. Enablement evidence'!$D$2:$D$400,"Generic"),"incomplete "&COUNTIFS('3. Enablement evidence'!$A$2:$A$400,$A12,'3. Enablement evidence'!$D$2:$D$400,"Generic",'3. Enablement evidence'!$G$2:$G$400,"Yes")&"/"&COUNTIFS('3. Enablement evidence'!$A$2:$A$400,$A12,'3. Enablement evidence'!$D$2:$D$400,"Generic"),IF(COUNTIFS('3. Enablement evidence'!$A$2:$A$400,$A12,'3. Enablement evidence'!$D$2:$D$400,"Generic",'3. Enablement evidence'!$G$2:$G$400,"Yes")>=8,4,IF(AND(COUNTIFS('3. Enablement evidence'!$A$2:$A$400,$A12,'3. Enablement evidence'!$C$2:$C$400,"Published standard",'3. Enablement evidence'!$G$2:$G$400,"Yes")=1,COUNTIFS('3. Enablement evidence'!$A$2:$A$400,$A12,'3. Enablement evidence'!$C$2:$C$400,"Architecture pattern document",'3. Enablement evidence'!$G$2:$G$400,"Yes")+COUNTIFS('3. Enablement evidence'!$A$2:$A$400,$A12,'3. Enablement evidence'!$C$2:$C$400,"Reference architecture",'3. Enablement evidence'!$G$2:$G$400,"Yes")>=1),3,IF(COUNTIFS('3. Enablement evidence'!$A$2:$A$400,$A12,'3. Enablement evidence'!$D$2:$D$400,"Generic",'3. Enablement evidence'!$G$2:$G$400,"Yes")>=1,2,1)))))) | K12: Candidate
A13: REAL-203 | B13: 3.5 | D13: S1.4 Table Extraction | I13: =IF(COUNTIFS('3. Enablement evidence'!$A$2:$A$400,$A13,'3. Enablement evidence'!$D$2:$D$400,"Generic")=0,"",IF(COUNTIFS('3. Enablement evidence'!$A$2:$A$400,$A13,'3. Enablement evidence'!$D$2:$D$400,"Generic",'3. Enablement evidence'!$G$2:$G$400,"Yes")+COUNTIFS('3. Enablement evidence'!$A$2:$A$400,$A13,'3. Enablement evidence'!$D$2:$D$400,"Generic",'3. Enablement evidence'!$G$2:$G$400,"No")+COUNTIFS('3. Enablement evidence'!$A$2:$A$400,$A13,'3. Enablement evidence'!$D$2:$D$400,"Generic",'3. Enablement evidence'!$G$2:$G$400,"Partial")=0,"no evidence",IF(COUNTIFS('3. Enablement evidence'!$A$2:$A$400,$A13,'3. Enablement evidence'!$D$2:$D$400,"Generic",'3. Enablement evidence'!$G$2:$G$400,"Yes")+COUNTIFS('3. Enablement evidence'!$A$2:$A$400,$A13,'3. Enablement evidence'!$D$2:$D$400,"Generic",'3. Enablement evidence'!$G$2:$G$400,"No")+COUNTIFS('3. Enablement evidence'!$A$2:$A$400,$A13,'3. Enablement evidence'!$D$2:$D$400,"Generic",'3. Enablement evidence'!$G$2:$G$400,"Partial")<COUNTIFS('3. Enablement evidence'!$A$2:$A$400,$A13,'3. Enablement evidence'!$D$2:$D$400,"Generic"),"incomplete "&COUNTIFS('3. Enablement evidence'!$A$2:$A$400,$A13,'3. Enablement evidence'!$D$2:$D$400,"Generic",'3. Enablement evidence'!$G$2:$G$400,"Yes")&"/"&COUNTIFS('3. Enablement evidence'!$A$2:$A$400,$A13,'3. Enablement evidence'!$D$2:$D$400,"Generic"),IF(COUNTIFS('3. Enablement evidence'!$A$2:$A$400,$A13,'3. Enablement evidence'!$D$2:$D$400,"Generic",'3. Enablement evidence'!$G$2:$G$400,"Yes")>=8,4,IF(AND(COUNTIFS('3. Enablement evidence'!$A$2:$A$400,$A13,'3. Enablement evidence'!$C$2:$C$400,"Published standard",'3. Enablement evidence'!$G$2:$G$400,"Yes")=1,COUNTIFS('3. Enablement evidence'!$A$2:$A$400,$A13,'3. Enablement evidence'!$C$2:$C$400,"Architecture pattern document",'3. Enablement evidence'!$G$2:$G$400,"Yes")+COUNTIFS('3. Enablement evidence'!$A$2:$A$400,$A13,'3. Enablement evidence'!$C$2:$C$400,"Reference architecture",'3. Enablement evidence'!$G$2:$G$400,"Yes")>=1),3,IF(COUNTIFS('3. Enablement evidence'!$A$2:$A$400,$A13,'3. Enablement evidence'!$D$2:$D$400,"Generic",'3. Enablement evidence'!$G$2:$G$400,"Yes")>=1,2,1)))))) | K13: Candidate
A14: REAL-204 | B14: 3.5 | D14: S1.5 Document Classification & Splitting | I14: =IF(COUNTIFS('3. Enablement evidence'!$A$2:$A$400,$A14,'3. Enablement evidence'!$D$2:$D$400,"Generic")=0,"",IF(COUNTIFS('3. Enablement evidence'!$A$2:$A$400,$A14,'3. Enablement evidence'!$D$2:$D$400,"Generic",'3. Enablement evidence'!$G$2:$G$400,"Yes")+COUNTIFS('3. Enablement evidence'!$A$2:$A$400,$A14,'3. Enablement evidence'!$D$2:$D$400,"Generic",'3. Enablement evidence'!$G$2:$G$400,"No")+COUNTIFS('3. Enablement evidence'!$A$2:$A$400,$A14,'3. Enablement evidence'!$D$2:$D$400,"Generic",'3. Enablement evidence'!$G$2:$G$400,"Partial")=0,"no evidence",IF(COUNTIFS('3. Enablement evidence'!$A$2:$A$400,$A14,'3. Enablement evidence'!$D$2:$D$400,"Generic",'3. Enablement evidence'!$G$2:$G$400,"Yes")+COUNTIFS('3. Enablement evidence'!$A$2:$A$400,$A14,'3. Enablement evidence'!$D$2:$D$400,"Generic",'3. Enablement evidence'!$G$2:$G$400,"No")+COUNTIFS('3. Enablement evidence'!$A$2:$A$400,$A14,'3. Enablement evidence'!$D$2:$D$400,"Generic",'3. Enablement evidence'!$G$2:$G$400,"Partial")<COUNTIFS('3. Enablement evidence'!$A$2:$A$400,$A14,'3. Enablement evidence'!$D$2:$D$400,"Generic"),"incomplete "&COUNTIFS('3. Enablement evidence'!$A$2:$A$400,$A14,'3. Enablement evidence'!$D$2:$D$400,"Generic",'3. Enablement evidence'!$G$2:$G$400,"Yes")&"/"&COUNTIFS('3. Enablement evidence'!$A$2:$A$400,$A14,'3. Enablement evidence'!$D$2:$D$400,"Generic"),IF(COUNTIFS('3. Enablement evidence'!$A$2:$A$400,$A14,'3. Enablement evidence'!$D$2:$D$400,"Generic",'3. Enablement evidence'!$G$2:$G$400,"Yes")>=8,4,IF(AND(COUNTIFS('3. Enablement evidence'!$A$2:$A$400,$A14,'3. Enablement evidence'!$C$2:$C$400,"Published standard",'3. Enablement evidence'!$G$2:$G$400,"Yes")=1,COUNTIFS('3. Enablement evidence'!$A$2:$A$400,$A14,'3. Enablement evidence'!$C$2:$C$400,"Architecture pattern document",'3. Enablement evidence'!$G$2:$G$400,"Yes")+COUNTIFS('3. Enablement evidence'!$A$2:$A$400,$A14,'3. Enablement evidence'!$C$2:$C$400,"Reference architecture",'3. Enablement evidence'!$G$2:$G$400,"Yes")>=1),3,IF(COUNTIFS('3. Enablement evidence'!$A$2:$A$400,$A14,'3. Enablement evidence'!$D$2:$D$400,"Generic",'3. Enablement evidence'!$G$2:$G$400,"Yes")>=1,2,1)))))) | K14: Candidate
A15: REAL-205 | B15: 3.5 | D15: S1.6 Handwriting Recognition | I15: =IF(COUNTIFS('3. Enablement evidence'!$A$2:$A$400,$A15,'3. Enablement evidence'!$D$2:$D$400,"Generic")=0,"",IF(COUNTIFS('3. Enablement evidence'!$A$2:$A$400,$A15,'3. Enablement evidence'!$D$2:$D$400,"Generic",'3. Enablement evidence'!$G$2:$G$400,"Yes")+COUNTIFS('3. Enablement evidence'!$A$2:$A$400,$A15,'3. Enablement evidence'!$D$2:$D$400,"Generic",'3. Enablement evidence'!$G$2:$G$400,"No")+COUNTIFS('3. Enablement evidence'!$A$2:$A$400,$A15,'3. Enablement evidence'!$D$2:$D$400,"Generic",'3. Enablement evidence'!$G$2:$G$400,"Partial")=0,"no evidence",IF(COUNTIFS('3. Enablement evidence'!$A$2:$A$400,$A15,'3. Enablement evidence'!$D$2:$D$400,"Generic",'3. Enablement evidence'!$G$2:$G$400,"Yes")+COUNTIFS('3. Enablement evidence'!$A$2:$A$400,$A15,'3. Enablement evidence'!$D$2:$D$400,"Generic",'3. Enablement evidence'!$G$2:$G$400,"No")+COUNTIFS('3. Enablement evidence'!$A$2:$A$400,$A15,'3. Enablement evidence'!$D$2:$D$400,"Generic",'3. Enablement evidence'!$G$2:$G$400,"Partial")<COUNTIFS('3. Enablement evidence'!$A$2:$A$400,$A15,'3. Enablement evidence'!$D$2:$D$400,"Generic"),"incomplete "&COUNTIFS('3. Enablement evidence'!$A$2:$A$400,$A15,'3. Enablement evidence'!$D$2:$D$400,"Generic",'3. Enablement evidence'!$G$2:$G$400,"Yes")&"/"&COUNTIFS('3. Enablement evidence'!$A$2:$A$400,$A15,'3. Enablement evidence'!$D$2:$D$400,"Generic"),IF(COUNTIFS('3. Enablement evidence'!$A$2:$A$400,$A15,'3. Enablement evidence'!$D$2:$D$400,"Generic",'3. Enablement evidence'!$G$2:$G$400,"Yes")>=8,4,IF(AND(COUNTIFS('3. Enablement evidence'!$A$2:$A$400,$A15,'3. Enablement evidence'!$C$2:$C$400,"Published standard",'3. Enablement evidence'!$G$2:$G$400,"Yes")=1,COUNTIFS('3. Enablement evidence'!$A$2:$A$400,$A15,'3. Enablement evidence'!$C$2:$C$400,"Architecture pattern document",'3. Enablement evidence'!$G$2:$G$400,"Yes")+COUNTIFS('3. Enablement evidence'!$A$2:$A$400,$A15,'3. Enablement evidence'!$C$2:$C$400,"Reference architecture",'3. Enablement evidence'!$G$2:$G$400,"Yes")>=1),3,IF(COUNTIFS('3. Enablement evidence'!$A$2:$A$400,$A15,'3. Enablement evidence'!$D$2:$D$400,"Generic",'3. Enablement evidence'!$G$2:$G$400,"Yes")>=1,2,1)))))) | K15: Candidate
A16: REAL-206 | B16: 3.5 | D16: S1.7 Speech-to-Text | I16: =IF(COUNTIFS('3. Enablement evidence'!$A$2:$A$400,$A16,'3. Enablement evidence'!$D$2:$D$400,"Generic")=0,"",IF(COUNTIFS('3. Enablement evidence'!$A$2:$A$400,$A16,'3. Enablement evidence'!$D$2:$D$400,"Generic",'3. Enablement evidence'!$G$2:$G$400,"Yes")+COUNTIFS('3. Enablement evidence'!$A$2:$A$400,$A16,'3. Enablement evidence'!$D$2:$D$400,"Generic",'3. Enablement evidence'!$G$2:$G$400,"No")+COUNTIFS('3. Enablement evidence'!$A$2:$A$400,$A16,'3. Enablement evidence'!$D$2:$D$400,"Generic",'3. Enablement evidence'!$G$2:$G$400,"Partial")=0,"no evidence",IF(COUNTIFS('3. Enablement evidence'!$A$2:$A$400,$A16,'3. Enablement evidence'!$D$2:$D$400,"Generic",'3. Enablement evidence'!$G$2:$G$400,"Yes")+COUNTIFS('3. Enablement evidence'!$A$2:$A$400,$A16,'3. Enablement evidence'!$D$2:$D$400,"Generic",'3. Enablement evidence'!$G$2:$G$400,"No")+COUNTIFS('3. Enablement evidence'!$A$2:$A$400,$A16,'3. Enablement evidence'!$D$2:$D$400,"Generic",'3. Enablement evidence'!$G$2:$G$400,"Partial")<COUNTIFS('3. Enablement evidence'!$A$2:$A$400,$A16,'3. Enablement evidence'!$D$2:$D$400,"Generic"),"incomplete "&COUNTIFS('3. Enablement evidence'!$A$2:$A$400,$A16,'3. Enablement evidence'!$D$2:$D$400,"Generic",'3. Enablement evidence'!$G$2:$G$400,"Yes")&"/"&COUNTIFS('3. Enablement evidence'!$A$2:$A$400,$A16,'3. Enablement evidence'!$D$2:$D$400,"Generic"),IF(COUNTIFS('3. Enablement evidence'!$A$2:$A$400,$A16,'3. Enablement evidence'!$D$2:$D$400,"Generic",'3. Enablement evidence'!$G$2:$G$400,"Yes")>=8,4,IF(AND(COUNTIFS('3. Enablement evidence'!$A$2:$A$400,$A16,'3. Enablement evidence'!$C$2:$C$400,"Published standard",'3. Enablement evidence'!$G$2:$G$400,"Yes")=1,COUNTIFS('3. Enablement evidence'!$A$2:$A$400,$A16,'3. Enablement evidence'!$C$2:$C$400,"Architecture pattern document",'3. Enablement evidence'!$G$2:$G$400,"Yes")+COUNTIFS('3. Enablement evidence'!$A$2:$A$400,$A16,'3. Enablement evidence'!$C$2:$C$400,"Reference architecture",'3. Enablement evidence'!$G$2:$G$400,"Yes")>=1),3,IF(COUNTIFS('3. Enablement evidence'!$A$2:$A$400,$A16,'3. Enablement evidence'!$D$2:$D$400,"Generic",'3. Enablement evidence'!$G$2:$G$400,"Yes")>=1,2,1)))))) | K16: Candidate
A17: REAL-207 | D17: S1.8 Speaker Diarization & Recognition | I17: =IF(COUNTIFS('3. Enablement evidence'!$A$2:$A$400,$A17,'3. Enablement evidence'!$D$2:$D$400,"Generic")=0,"",IF(COUNTIFS('3. Enablement evidence'!$A$2:$A$400,$A17,'3. Enablement evidence'!$D$2:$D$400,"Generic",'3. Enablement evidence'!$G$2:$G$400,"Yes")+COUNTIFS('3. Enablement evidence'!$A$2:$A$400,$A17,'3. Enablement evidence'!$D$2:$D$400,"Generic",'3. Enablement evidence'!$G$2:$G$400,"No")+COUNTIFS('3. Enablement evidence'!$A$2:$A$400,$A17,'3. Enablement evidence'!$D$2:$D$400,"Generic",'3. Enablement evidence'!$G$2:$G$400,"Partial")=0,"no evidence",IF(COUNTIFS('3. Enablement evidence'!$A$2:$A$400,$A17,'3. Enablement evidence'!$D$2:$D$400,"Generic",'3. Enablement evidence'!$G$2:$G$400,"Yes")+COUNTIFS('3. Enablement evidence'!$A$2:$A$400,$A17,'3. Enablement evidence'!$D$2:$D$400,"Generic",'3. Enablement evidence'!$G$2:$G$400,"No")+COUNTIFS('3. Enablement evidence'!$A$2:$A$400,$A17,'3. Enablement evidence'!$D$2:$D$400,"Generic",'3. Enablement evidence'!$G$2:$G$400,"Partial")<COUNTIFS('3. Enablement evidence'!$A$2:$A$400,$A17,'3. Enablement evidence'!$D$2:$D$400,"Generic"),"incomplete "&COUNTIFS('3. Enablement evidence'!$A$2:$A$400,$A17,'3. Enablement evidence'!$D$2:$D$400,"Generic",'3. Enablement evidence'!$G$2:$G$400,"Yes")&"/"&COUNTIFS('3. Enablement evidence'!$A$2:$A$400,$A17,'3. Enablement evidence'!$D$2:$D$400,"Generic"),IF(COUNTIFS('3. Enablement evidence'!$A$2:$A$400,$A17,'3. Enablement evidence'!$D$2:$D$400,"Generic",'3. Enablement evidence'!$G$2:$G$400,"Yes")>=8,4,IF(AND(COUNTIFS('3. Enablement evidence'!$A$2:$A$400,$A17,'3. Enablement evidence'!$C$2:$C$400,"Published standard",'3. Enablement evidence'!$G$2:$G$400,"Yes")=1,COUNTIFS('3. Enablement evidence'!$A$2:$A$400,$A17,'3. Enablement evidence'!$C$2:$C$400,"Architecture pattern document",'3. Enablement evidence'!$G$2:$G$400,"Yes")+COUNTIFS('3. Enablement evidence'!$A$2:$A$400,$A17,'3. Enablement evidence'!$C$2:$C$400,"Reference architecture",'3. Enablement evidence'!$G$2:$G$400,"Yes")>=1),3,IF(COUNTIFS('3. Enablement evidence'!$A$2:$A$400,$A17,'3. Enablement evidence'!$D$2:$D$400,"Generic",'3. Enablement evidence'!$G$2:$G$400,"Yes")>=1,2,1)))))) | K17: Candidate
